info: Server started at http://localhost:3000/api/v1/ {"timestamp":"2022-09-21T18:30:55.477Z"}
info: Connected to the database. {"timestamp":"2022-09-21T18:30:55.572Z"}
info: Server started at http://localhost:3000/api/v1/ {"timestamp":"2022-09-21T18:31:11.669Z"}
info: Connected to the database. {"timestamp":"2022-09-21T18:31:11.729Z"}
info: Server started at http://localhost:3000/api/v1/ {"timestamp":"2022-09-21T18:31:29.727Z"}
info: Connected to the database. {"timestamp":"2022-09-21T18:31:29.763Z"}
info: Server started at http://localhost:3000/api/v1/ {"timestamp":"2022-09-21T18:31:58.364Z"}
info: Connected to the database. {"timestamp":"2022-09-21T18:31:58.407Z"}
error: 
    status - 500 
    message - JsonWebTokenError: invalid signature
    at E:\Fundoo_test\node_modules\jsonwebtoken\verify.js:133:19
    at getSecret (E:\Fundoo_test\node_modules\jsonwebtoken\verify.js:90:14)
    at Object.verify (E:\Fundoo_test\node_modules\jsonwebtoken\verify.js:94:10)
    at _callee$ (E:\Fundoo_test\src\middlewares\/auth.middleware.js:22:32)
    at tryCatch (E:\Fundoo_test\node_modules\@babel\runtime\helpers\regeneratorRuntime.js:86:17)
    at Generator._invoke (E:\Fundoo_test\node_modules\@babel\runtime\helpers\regeneratorRuntime.js:66:24)
    at Generator.next (E:\Fundoo_test\node_modules\@babel\runtime\helpers\regeneratorRuntime.js:117:21)
    at asyncGeneratorStep (E:\Fundoo_test\node_modules\@babel\runtime\helpers\asyncToGenerator.js:3:24)
    at _next (E:\Fundoo_test\node_modules\@babel\runtime\helpers\asyncToGenerator.js:25:9)
    at E:\Fundoo_test\node_modules\@babel\runtime\helpers\asyncToGenerator.js:32:7
    at new Promise (<anonymous>)
    at E:\Fundoo_test\node_modules\@babel\runtime\helpers\asyncToGenerator.js:21:12
    at userAuth (E:\Fundoo_test\src\middlewares\/auth.middleware.js:12:22)
    at Layer.handle [as handle_request] (E:\Fundoo_test\node_modules\express\lib\router\layer.js:95:5)
    at next (E:\Fundoo_test\node_modules\express\lib\router\route.js:144:13)
    at newNoteValidator (E:\Fundoo_test\src\validators\/user.validator.js:29:5)
    at Layer.handle [as handle_request] (E:\Fundoo_test\node_modules\express\lib\router\layer.js:95:5)
    at next (E:\Fundoo_test\node_modules\express\lib\router\route.js:144:13)
    at Route.dispatch (E:\Fundoo_test\node_modules\express\lib\router\route.js:114:3)
    at Layer.handle [as handle_request] (E:\Fundoo_test\node_modules\express\lib\router\layer.js:95:5)
    at E:\Fundoo_test\node_modules\express\lib\router\index.js:284:15
    at Function.process_params (E:\Fundoo_test\node_modules\express\lib\router\index.js:346:12)
    at next (E:\Fundoo_test\node_modules\express\lib\router\index.js:280:10)
    at Function.handle (E:\Fundoo_test\node_modules\express\lib\router\index.js:175:3)
    at router (E:\Fundoo_test\node_modules\express\lib\router\index.js:47:12)
    at Layer.handle [as handle_request] (E:\Fundoo_test\node_modules\express\lib\router\layer.js:95:5)
    at trim_prefix (E:\Fundoo_test\node_modules\express\lib\router\index.js:328:13)
    at E:\Fundoo_test\node_modules\express\lib\router\index.js:286:9
    at Function.process_params (E:\Fundoo_test\node_modules\express\lib\router\index.js:346:12)
    at next (E:\Fundoo_test\node_modules\express\lib\router\index.js:280:10)
    at Function.handle (E:\Fundoo_test\node_modules\express\lib\router\index.js:175:3)
    at router (E:\Fundoo_test\node_modules\express\lib\router\index.js:47:12)
    at Layer.handle [as handle_request] (E:\Fundoo_test\node_modules\express\lib\router\layer.js:95:5)
    at trim_prefix (E:\Fundoo_test\node_modules\express\lib\router\index.js:328:13)
    at E:\Fundoo_test\node_modules\express\lib\router\index.js:286:9
    at Function.process_params (E:\Fundoo_test\node_modules\express\lib\router\index.js:346:12)
    at next (E:\Fundoo_test\node_modules\express\lib\router\index.js:280:10)
    at logger (E:\Fundoo_test\node_modules\morgan\index.js:144:5)
    at Layer.handle [as handle_request] (E:\Fundoo_test\node_modules\express\lib\router\layer.js:95:5)
    at trim_prefix (E:\Fundoo_test\node_modules\express\lib\router\index.js:328:13)
    at E:\Fundoo_test\node_modules\express\lib\router\index.js:286:9
    at Function.process_params (E:\Fundoo_test\node_modules\express\lib\router\index.js:346:12)
    at next (E:\Fundoo_test\node_modules\express\lib\router\index.js:280:10)
    at E:\Fundoo_test\node_modules\body-parser\lib\read.js:137:5
    at AsyncResource.runInAsyncScope (node:async_hooks:203:9)
    at invokeCallback (E:\Fundoo_test\node_modules\raw-body\index.js:231:16)
    at done (E:\Fundoo_test\node_modules\raw-body\index.js:220:7)
    at IncomingMessage.onEnd (E:\Fundoo_test\node_modules\raw-body\index.js:280:7)
    at IncomingMessage.emit (node:events:525:35)
    at IncomingMessage.emit (node:domain:489:12) 
    url - /api/v1/note/note 
    method - POST 
    IP - ::1
   {"timestamp":"2022-09-21T18:35:30.970Z"}
error: 
    status - 500 
    message - JsonWebTokenError: invalid signature
    at E:\Fundoo_test\node_modules\jsonwebtoken\verify.js:133:19
    at getSecret (E:\Fundoo_test\node_modules\jsonwebtoken\verify.js:90:14)
    at Object.verify (E:\Fundoo_test\node_modules\jsonwebtoken\verify.js:94:10)
    at _callee$ (E:\Fundoo_test\src\middlewares\/auth.middleware.js:22:32)
    at tryCatch (E:\Fundoo_test\node_modules\@babel\runtime\helpers\regeneratorRuntime.js:86:17)
    at Generator._invoke (E:\Fundoo_test\node_modules\@babel\runtime\helpers\regeneratorRuntime.js:66:24)
    at Generator.next (E:\Fundoo_test\node_modules\@babel\runtime\helpers\regeneratorRuntime.js:117:21)
    at asyncGeneratorStep (E:\Fundoo_test\node_modules\@babel\runtime\helpers\asyncToGenerator.js:3:24)
    at _next (E:\Fundoo_test\node_modules\@babel\runtime\helpers\asyncToGenerator.js:25:9)
    at E:\Fundoo_test\node_modules\@babel\runtime\helpers\asyncToGenerator.js:32:7
    at new Promise (<anonymous>)
    at E:\Fundoo_test\node_modules\@babel\runtime\helpers\asyncToGenerator.js:21:12
    at userAuth (E:\Fundoo_test\src\middlewares\/auth.middleware.js:12:22)
    at Layer.handle [as handle_request] (E:\Fundoo_test\node_modules\express\lib\router\layer.js:95:5)
    at next (E:\Fundoo_test\node_modules\express\lib\router\route.js:144:13)
    at newNoteValidator (E:\Fundoo_test\src\validators\/user.validator.js:29:5)
    at Layer.handle [as handle_request] (E:\Fundoo_test\node_modules\express\lib\router\layer.js:95:5)
    at next (E:\Fundoo_test\node_modules\express\lib\router\route.js:144:13)
    at Route.dispatch (E:\Fundoo_test\node_modules\express\lib\router\route.js:114:3)
    at Layer.handle [as handle_request] (E:\Fundoo_test\node_modules\express\lib\router\layer.js:95:5)
    at E:\Fundoo_test\node_modules\express\lib\router\index.js:284:15
    at Function.process_params (E:\Fundoo_test\node_modules\express\lib\router\index.js:346:12)
    at next (E:\Fundoo_test\node_modules\express\lib\router\index.js:280:10)
    at Function.handle (E:\Fundoo_test\node_modules\express\lib\router\index.js:175:3)
    at router (E:\Fundoo_test\node_modules\express\lib\router\index.js:47:12)
    at Layer.handle [as handle_request] (E:\Fundoo_test\node_modules\express\lib\router\layer.js:95:5)
    at trim_prefix (E:\Fundoo_test\node_modules\express\lib\router\index.js:328:13)
    at E:\Fundoo_test\node_modules\express\lib\router\index.js:286:9
    at Function.process_params (E:\Fundoo_test\node_modules\express\lib\router\index.js:346:12)
    at next (E:\Fundoo_test\node_modules\express\lib\router\index.js:280:10)
    at Function.handle (E:\Fundoo_test\node_modules\express\lib\router\index.js:175:3)
    at router (E:\Fundoo_test\node_modules\express\lib\router\index.js:47:12)
    at Layer.handle [as handle_request] (E:\Fundoo_test\node_modules\express\lib\router\layer.js:95:5)
    at trim_prefix (E:\Fundoo_test\node_modules\express\lib\router\index.js:328:13)
    at E:\Fundoo_test\node_modules\express\lib\router\index.js:286:9
    at Function.process_params (E:\Fundoo_test\node_modules\express\lib\router\index.js:346:12)
    at next (E:\Fundoo_test\node_modules\express\lib\router\index.js:280:10)
    at logger (E:\Fundoo_test\node_modules\morgan\index.js:144:5)
    at Layer.handle [as handle_request] (E:\Fundoo_test\node_modules\express\lib\router\layer.js:95:5)
    at trim_prefix (E:\Fundoo_test\node_modules\express\lib\router\index.js:328:13)
    at E:\Fundoo_test\node_modules\express\lib\router\index.js:286:9
    at Function.process_params (E:\Fundoo_test\node_modules\express\lib\router\index.js:346:12)
    at next (E:\Fundoo_test\node_modules\express\lib\router\index.js:280:10)
    at E:\Fundoo_test\node_modules\body-parser\lib\read.js:137:5
    at AsyncResource.runInAsyncScope (node:async_hooks:203:9)
    at invokeCallback (E:\Fundoo_test\node_modules\raw-body\index.js:231:16)
    at done (E:\Fundoo_test\node_modules\raw-body\index.js:220:7)
    at IncomingMessage.onEnd (E:\Fundoo_test\node_modules\raw-body\index.js:280:7)
    at IncomingMessage.emit (node:events:525:35)
    at IncomingMessage.emit (node:domain:489:12) 
    url - /api/v1/note/note 
    method - POST 
    IP - ::1
   {"timestamp":"2022-09-21T18:35:40.241Z"}
info: Server started at http://localhost:3000/api/v1/ {"timestamp":"2022-09-21T18:40:36.218Z"}
info: Connected to the database. {"timestamp":"2022-09-21T18:40:36.406Z"}
info: Server started at http://localhost:3000/api/v1/ {"timestamp":"2022-09-21T18:42:29.039Z"}
info: Connected to the database. {"timestamp":"2022-09-21T18:42:29.116Z"}
info: Server started at http://localhost:3000/api/v1/ {"timestamp":"2022-09-21T18:42:46.744Z"}
info: Connected to the database. {"timestamp":"2022-09-21T18:42:47.062Z"}
info: Server started at http://localhost:3000/api/v1/ {"timestamp":"2022-09-21T18:43:18.514Z"}
info: Connected to the database. {"timestamp":"2022-09-21T18:43:18.601Z"}
info: Server started at http://localhost:3000/api/v1/ {"timestamp":"2022-09-21T18:43:25.474Z"}
info: Connected to the database. {"timestamp":"2022-09-21T18:43:25.552Z"}
info: Server started at http://localhost:3000/api/v1/ {"timestamp":"2022-09-21T18:53:03.306Z"}
info: Connected to the database. {"timestamp":"2022-09-21T18:53:03.341Z"}
error: 
      status - 400
      message - Authorization token is required 
      url - /api/v1/note/note 
      method - POST 
      IP - ::1
     {"timestamp":"2022-09-21T19:09:35.699Z"}
info: Server started at http://localhost:3000/api/v1/ {"timestamp":"2022-09-22T03:22:44.161Z"}
info: Connected to the database. {"timestamp":"2022-09-22T03:22:44.250Z"}
info: Server started at http://localhost:3000/api/v1/ {"timestamp":"2022-09-22T14:27:45.290Z"}
info: Connected to the database. {"timestamp":"2022-09-22T14:27:45.324Z"}
error: 
    status - 500 
    message - ReferenceError: SECRETE_KEY is not defined
    at _callee$ (E:\Fundoo_test\src\middlewares\/auth.middleware.js:22:52)
    at tryCatch (E:\Fundoo_test\node_modules\@babel\runtime\helpers\regeneratorRuntime.js:86:17)
    at Generator._invoke (E:\Fundoo_test\node_modules\@babel\runtime\helpers\regeneratorRuntime.js:66:24)
    at Generator.next (E:\Fundoo_test\node_modules\@babel\runtime\helpers\regeneratorRuntime.js:117:21)
    at asyncGeneratorStep (E:\Fundoo_test\node_modules\@babel\runtime\helpers\asyncToGenerator.js:3:24)
    at _next (E:\Fundoo_test\node_modules\@babel\runtime\helpers\asyncToGenerator.js:25:9)
    at E:\Fundoo_test\node_modules\@babel\runtime\helpers\asyncToGenerator.js:32:7
    at new Promise (<anonymous>)
    at E:\Fundoo_test\node_modules\@babel\runtime\helpers\asyncToGenerator.js:21:12
    at userAuth (E:\Fundoo_test\src\middlewares\/auth.middleware.js:12:22)
    at Layer.handle [as handle_request] (E:\Fundoo_test\node_modules\express\lib\router\layer.js:95:5)
    at next (E:\Fundoo_test\node_modules\express\lib\router\route.js:144:13)
    at newNoteValidator (E:\Fundoo_test\src\validators\/user.validator.js:29:5)
    at Layer.handle [as handle_request] (E:\Fundoo_test\node_modules\express\lib\router\layer.js:95:5)
    at next (E:\Fundoo_test\node_modules\express\lib\router\route.js:144:13)
    at Route.dispatch (E:\Fundoo_test\node_modules\express\lib\router\route.js:114:3)
    at Layer.handle [as handle_request] (E:\Fundoo_test\node_modules\express\lib\router\layer.js:95:5)
    at E:\Fundoo_test\node_modules\express\lib\router\index.js:284:15
    at Function.process_params (E:\Fundoo_test\node_modules\express\lib\router\index.js:346:12)
    at next (E:\Fundoo_test\node_modules\express\lib\router\index.js:280:10)
    at Function.handle (E:\Fundoo_test\node_modules\express\lib\router\index.js:175:3)
    at router (E:\Fundoo_test\node_modules\express\lib\router\index.js:47:12)
    at Layer.handle [as handle_request] (E:\Fundoo_test\node_modules\express\lib\router\layer.js:95:5)
    at trim_prefix (E:\Fundoo_test\node_modules\express\lib\router\index.js:328:13)
    at E:\Fundoo_test\node_modules\express\lib\router\index.js:286:9
    at Function.process_params (E:\Fundoo_test\node_modules\express\lib\router\index.js:346:12)
    at next (E:\Fundoo_test\node_modules\express\lib\router\index.js:280:10)
    at Function.handle (E:\Fundoo_test\node_modules\express\lib\router\index.js:175:3)
    at router (E:\Fundoo_test\node_modules\express\lib\router\index.js:47:12)
    at Layer.handle [as handle_request] (E:\Fundoo_test\node_modules\express\lib\router\layer.js:95:5)
    at trim_prefix (E:\Fundoo_test\node_modules\express\lib\router\index.js:328:13)
    at E:\Fundoo_test\node_modules\express\lib\router\index.js:286:9
    at Function.process_params (E:\Fundoo_test\node_modules\express\lib\router\index.js:346:12)
    at next (E:\Fundoo_test\node_modules\express\lib\router\index.js:280:10)
    at logger (E:\Fundoo_test\node_modules\morgan\index.js:144:5)
    at Layer.handle [as handle_request] (E:\Fundoo_test\node_modules\express\lib\router\layer.js:95:5)
    at trim_prefix (E:\Fundoo_test\node_modules\express\lib\router\index.js:328:13)
    at E:\Fundoo_test\node_modules\express\lib\router\index.js:286:9
    at Function.process_params (E:\Fundoo_test\node_modules\express\lib\router\index.js:346:12)
    at next (E:\Fundoo_test\node_modules\express\lib\router\index.js:280:10)
    at E:\Fundoo_test\node_modules\body-parser\lib\read.js:137:5
    at AsyncResource.runInAsyncScope (node:async_hooks:203:9)
    at invokeCallback (E:\Fundoo_test\node_modules\raw-body\index.js:231:16)
    at done (E:\Fundoo_test\node_modules\raw-body\index.js:220:7)
    at IncomingMessage.onEnd (E:\Fundoo_test\node_modules\raw-body\index.js:280:7)
    at IncomingMessage.emit (node:events:525:35)
    at IncomingMessage.emit (node:domain:489:12)
    at endReadableNT (node:internal/streams/readable:1358:12)
    at processTicksAndRejections (node:internal/process/task_queues:83:21) 
    url - /api/v1/note/note 
    method - POST 
    IP - ::1
   {"timestamp":"2022-09-22T14:28:47.185Z"}
info: Server started at http://localhost:3000/api/v1/ {"timestamp":"2022-09-22T14:29:22.545Z"}
info: Connected to the database. {"timestamp":"2022-09-22T14:29:22.617Z"}
info: Server started at http://localhost:3000/api/v1/ {"timestamp":"2022-09-22T14:30:39.134Z"}
info: Connected to the database. {"timestamp":"2022-09-22T14:30:39.222Z"}
info: Server started at http://localhost:3000/api/v1/ {"timestamp":"2022-09-22T14:31:03.772Z"}
info: Connected to the database. {"timestamp":"2022-09-22T14:31:03.854Z"}
info: Server started at http://localhost:3000/api/v1/ {"timestamp":"2022-09-22T14:33:12.716Z"}
info: Connected to the database. {"timestamp":"2022-09-22T14:33:12.790Z"}
info: Server started at http://localhost:3000/api/v1/ {"timestamp":"2022-09-22T14:33:33.687Z"}
info: Connected to the database. {"timestamp":"2022-09-22T14:33:33.727Z"}
info: Server started at http://localhost:3000/api/v1/ {"timestamp":"2022-09-22T14:34:53.758Z"}
info: Connected to the database. {"timestamp":"2022-09-22T14:34:53.843Z"}
info: Server started at http://localhost:3000/api/v1/ {"timestamp":"2022-09-22T14:36:31.790Z"}
info: Connected to the database. {"timestamp":"2022-09-22T14:36:31.860Z"}
info: Server started at http://localhost:3000/api/v1/ {"timestamp":"2022-09-22T14:36:48.967Z"}
info: Connected to the database. {"timestamp":"2022-09-22T14:36:49.023Z"}
info: Server started at http://localhost:3000/api/v1/ {"timestamp":"2022-09-22T14:37:06.740Z"}
info: Connected to the database. {"timestamp":"2022-09-22T14:37:06.825Z"}
info: Server started at http://localhost:3000/api/v1/ {"timestamp":"2022-09-22T14:38:13.605Z"}
info: Connected to the database. {"timestamp":"2022-09-22T14:38:13.669Z"}
info: Server started at http://localhost:3000/api/v1/ {"timestamp":"2022-09-22T14:38:22.545Z"}
info: Connected to the database. {"timestamp":"2022-09-22T14:38:22.591Z"}
info: Server started at http://localhost:3000/api/v1/ {"timestamp":"2022-09-22T15:21:46.638Z"}
info: Connected to the database. {"timestamp":"2022-09-22T15:21:46.672Z"}
info: Server started at http://localhost:3000/api/v1/ {"timestamp":"2022-09-22T15:22:17.556Z"}
info: Connected to the database. {"timestamp":"2022-09-22T15:22:17.622Z"}
info: Server started at http://localhost:3000/api/v1/ {"timestamp":"2022-09-22T15:22:23.309Z"}
info: Connected to the database. {"timestamp":"2022-09-22T15:22:23.351Z"}
info: Server started at http://localhost:3000/api/v1/ {"timestamp":"2022-09-22T15:22:29.066Z"}
info: Connected to the database. {"timestamp":"2022-09-22T15:22:29.192Z"}
info: Server started at http://localhost:3000/api/v1/ {"timestamp":"2022-09-22T15:23:11.050Z"}
info: Connected to the database. {"timestamp":"2022-09-22T15:23:11.075Z"}
info: Server started at http://localhost:3000/api/v1/ {"timestamp":"2022-09-22T15:25:57.576Z"}
info: Connected to the database. {"timestamp":"2022-09-22T15:25:57.631Z"}
info: Server started at http://localhost:3000/api/v1/ {"timestamp":"2022-09-22T15:40:12.044Z"}
info: Connected to the database. {"timestamp":"2022-09-22T15:40:12.213Z"}
error: 
    status - 500 
    message - ValidationError: "Title" length must be at least 6 characters long 
    url - /api/v1/note/note 
    method - POST 
    IP - ::1
   {"timestamp":"2022-09-22T15:40:38.745Z"}
error: 
    status - 500 
    message - ReferenceError: _id is not defined
    at _callee3$ (E:\Fundoo_test\src\services\/note.service.js:17:7)
    at tryCatch (E:\Fundoo_test\node_modules\@babel\runtime\helpers\regeneratorRuntime.js:86:17)
    at Generator._invoke (E:\Fundoo_test\node_modules\@babel\runtime\helpers\regeneratorRuntime.js:66:24)
    at Generator.next (E:\Fundoo_test\node_modules\@babel\runtime\helpers\regeneratorRuntime.js:117:21)
    at asyncGeneratorStep (E:\Fundoo_test\node_modules\@babel\runtime\helpers\asyncToGenerator.js:3:24)
    at _next (E:\Fundoo_test\node_modules\@babel\runtime\helpers\asyncToGenerator.js:25:9)
    at E:\Fundoo_test\node_modules\@babel\runtime\helpers\asyncToGenerator.js:32:7
    at new Promise (<anonymous>)
    at Object.<anonymous> (E:\Fundoo_test\node_modules\@babel\runtime\helpers\asyncToGenerator.js:21:12)
    at Object.updateNote (E:\Fundoo_test\src\services\/note.service.js:13:24)
    at _callee3$ (E:\Fundoo_test\src\controllers\/note.controller.js:33:36)
    at tryCatch (E:\Fundoo_test\node_modules\@babel\runtime\helpers\regeneratorRuntime.js:86:17)
    at Generator._invoke (E:\Fundoo_test\node_modules\@babel\runtime\helpers\regeneratorRuntime.js:66:24)
    at Generator.next (E:\Fundoo_test\node_modules\@babel\runtime\helpers\regeneratorRuntime.js:117:21)
    at asyncGeneratorStep (E:\Fundoo_test\node_modules\@babel\runtime\helpers\asyncToGenerator.js:3:24)
    at _next (E:\Fundoo_test\node_modules\@babel\runtime\helpers\asyncToGenerator.js:25:9)
    at E:\Fundoo_test\node_modules\@babel\runtime\helpers\asyncToGenerator.js:32:7
    at new Promise (<anonymous>)
    at E:\Fundoo_test\node_modules\@babel\runtime\helpers\asyncToGenerator.js:21:12
    at updateNote (E:\Fundoo_test\src\controllers\/note.controller.js:31:24)
    at Layer.handle [as handle_request] (E:\Fundoo_test\node_modules\express\lib\router\layer.js:95:5)
    at next (E:\Fundoo_test\node_modules\express\lib\router\route.js:144:13)
    at _callee$ (E:\Fundoo_test\src\middlewares\/auth.middleware.js:23:5)
    at tryCatch (E:\Fundoo_test\node_modules\@babel\runtime\helpers\regeneratorRuntime.js:86:17)
    at Generator._invoke (E:\Fundoo_test\node_modules\@babel\runtime\helpers\regeneratorRuntime.js:66:24)
    at Generator.next (E:\Fundoo_test\node_modules\@babel\runtime\helpers\regeneratorRuntime.js:117:21)
    at asyncGeneratorStep (E:\Fundoo_test\node_modules\@babel\runtime\helpers\asyncToGenerator.js:3:24)
    at _next (E:\Fundoo_test\node_modules\@babel\runtime\helpers\asyncToGenerator.js:25:9)
    at processTicksAndRejections (node:internal/process/task_queues:96:5) 
    url - /api/v1/note/632c81fee6151419b497a227 
    method - PUT 
    IP - ::1
   {"timestamp":"2022-09-22T15:41:13.272Z"}
error: 
    status - 500 
    message - ReferenceError: _id is not defined
    at _callee3$ (E:\Fundoo_test\src\services\/note.service.js:17:7)
    at tryCatch (E:\Fundoo_test\node_modules\@babel\runtime\helpers\regeneratorRuntime.js:86:17)
    at Generator._invoke (E:\Fundoo_test\node_modules\@babel\runtime\helpers\regeneratorRuntime.js:66:24)
    at Generator.next (E:\Fundoo_test\node_modules\@babel\runtime\helpers\regeneratorRuntime.js:117:21)
    at asyncGeneratorStep (E:\Fundoo_test\node_modules\@babel\runtime\helpers\asyncToGenerator.js:3:24)
    at _next (E:\Fundoo_test\node_modules\@babel\runtime\helpers\asyncToGenerator.js:25:9)
    at E:\Fundoo_test\node_modules\@babel\runtime\helpers\asyncToGenerator.js:32:7
    at new Promise (<anonymous>)
    at Object.<anonymous> (E:\Fundoo_test\node_modules\@babel\runtime\helpers\asyncToGenerator.js:21:12)
    at Object.updateNote (E:\Fundoo_test\src\services\/note.service.js:13:24)
    at _callee3$ (E:\Fundoo_test\src\controllers\/note.controller.js:33:36)
    at tryCatch (E:\Fundoo_test\node_modules\@babel\runtime\helpers\regeneratorRuntime.js:86:17)
    at Generator._invoke (E:\Fundoo_test\node_modules\@babel\runtime\helpers\regeneratorRuntime.js:66:24)
    at Generator.next (E:\Fundoo_test\node_modules\@babel\runtime\helpers\regeneratorRuntime.js:117:21)
    at asyncGeneratorStep (E:\Fundoo_test\node_modules\@babel\runtime\helpers\asyncToGenerator.js:3:24)
    at _next (E:\Fundoo_test\node_modules\@babel\runtime\helpers\asyncToGenerator.js:25:9)
    at E:\Fundoo_test\node_modules\@babel\runtime\helpers\asyncToGenerator.js:32:7
    at new Promise (<anonymous>)
    at E:\Fundoo_test\node_modules\@babel\runtime\helpers\asyncToGenerator.js:21:12
    at updateNote (E:\Fundoo_test\src\controllers\/note.controller.js:31:24)
    at Layer.handle [as handle_request] (E:\Fundoo_test\node_modules\express\lib\router\layer.js:95:5)
    at next (E:\Fundoo_test\node_modules\express\lib\router\route.js:144:13)
    at _callee$ (E:\Fundoo_test\src\middlewares\/auth.middleware.js:23:5)
    at tryCatch (E:\Fundoo_test\node_modules\@babel\runtime\helpers\regeneratorRuntime.js:86:17)
    at Generator._invoke (E:\Fundoo_test\node_modules\@babel\runtime\helpers\regeneratorRuntime.js:66:24)
    at Generator.next (E:\Fundoo_test\node_modules\@babel\runtime\helpers\regeneratorRuntime.js:117:21)
    at asyncGeneratorStep (E:\Fundoo_test\node_modules\@babel\runtime\helpers\asyncToGenerator.js:3:24)
    at _next (E:\Fundoo_test\node_modules\@babel\runtime\helpers\asyncToGenerator.js:25:9)
    at processTicksAndRejections (node:internal/process/task_queues:96:5) 
    url - /api/v1/note/632c81fee6151419b497a227 
    method - PUT 
    IP - ::1
   {"timestamp":"2022-09-22T15:41:24.526Z"}
error: 
    status - 500 
    message - ReferenceError: _id is not defined
    at _callee3$ (E:\Fundoo_test\src\services\/note.service.js:17:7)
    at tryCatch (E:\Fundoo_test\node_modules\@babel\runtime\helpers\regeneratorRuntime.js:86:17)
    at Generator._invoke (E:\Fundoo_test\node_modules\@babel\runtime\helpers\regeneratorRuntime.js:66:24)
    at Generator.next (E:\Fundoo_test\node_modules\@babel\runtime\helpers\regeneratorRuntime.js:117:21)
    at asyncGeneratorStep (E:\Fundoo_test\node_modules\@babel\runtime\helpers\asyncToGenerator.js:3:24)
    at _next (E:\Fundoo_test\node_modules\@babel\runtime\helpers\asyncToGenerator.js:25:9)
    at E:\Fundoo_test\node_modules\@babel\runtime\helpers\asyncToGenerator.js:32:7
    at new Promise (<anonymous>)
    at Object.<anonymous> (E:\Fundoo_test\node_modules\@babel\runtime\helpers\asyncToGenerator.js:21:12)
    at Object.updateNote (E:\Fundoo_test\src\services\/note.service.js:13:24)
    at _callee3$ (E:\Fundoo_test\src\controllers\/note.controller.js:33:36)
    at tryCatch (E:\Fundoo_test\node_modules\@babel\runtime\helpers\regeneratorRuntime.js:86:17)
    at Generator._invoke (E:\Fundoo_test\node_modules\@babel\runtime\helpers\regeneratorRuntime.js:66:24)
    at Generator.next (E:\Fundoo_test\node_modules\@babel\runtime\helpers\regeneratorRuntime.js:117:21)
    at asyncGeneratorStep (E:\Fundoo_test\node_modules\@babel\runtime\helpers\asyncToGenerator.js:3:24)
    at _next (E:\Fundoo_test\node_modules\@babel\runtime\helpers\asyncToGenerator.js:25:9)
    at E:\Fundoo_test\node_modules\@babel\runtime\helpers\asyncToGenerator.js:32:7
    at new Promise (<anonymous>)
    at E:\Fundoo_test\node_modules\@babel\runtime\helpers\asyncToGenerator.js:21:12
    at updateNote (E:\Fundoo_test\src\controllers\/note.controller.js:31:24)
    at Layer.handle [as handle_request] (E:\Fundoo_test\node_modules\express\lib\router\layer.js:95:5)
    at next (E:\Fundoo_test\node_modules\express\lib\router\route.js:144:13)
    at _callee$ (E:\Fundoo_test\src\middlewares\/auth.middleware.js:23:5)
    at tryCatch (E:\Fundoo_test\node_modules\@babel\runtime\helpers\regeneratorRuntime.js:86:17)
    at Generator._invoke (E:\Fundoo_test\node_modules\@babel\runtime\helpers\regeneratorRuntime.js:66:24)
    at Generator.next (E:\Fundoo_test\node_modules\@babel\runtime\helpers\regeneratorRuntime.js:117:21)
    at asyncGeneratorStep (E:\Fundoo_test\node_modules\@babel\runtime\helpers\asyncToGenerator.js:3:24)
    at _next (E:\Fundoo_test\node_modules\@babel\runtime\helpers\asyncToGenerator.js:25:9)
    at processTicksAndRejections (node:internal/process/task_queues:96:5) 
    url - /api/v1/note/632c81fee6151419b497a227 
    method - PUT 
    IP - ::1
   {"timestamp":"2022-09-22T15:41:25.736Z"}
error: 
    status - 500 
    message - ReferenceError: body is not defined
    at _callee4$ (E:\Fundoo_test\src\services\/note.service.js:27:15)
    at tryCatch (E:\Fundoo_test\node_modules\@babel\runtime\helpers\regeneratorRuntime.js:86:17)
    at Generator._invoke (E:\Fundoo_test\node_modules\@babel\runtime\helpers\regeneratorRuntime.js:66:24)
    at Generator.next (E:\Fundoo_test\node_modules\@babel\runtime\helpers\regeneratorRuntime.js:117:21)
    at asyncGeneratorStep (E:\Fundoo_test\node_modules\@babel\runtime\helpers\asyncToGenerator.js:3:24)
    at _next (E:\Fundoo_test\node_modules\@babel\runtime\helpers\asyncToGenerator.js:25:9)
    at E:\Fundoo_test\node_modules\@babel\runtime\helpers\asyncToGenerator.js:32:7
    at new Promise (<anonymous>)
    at Object.<anonymous> (E:\Fundoo_test\node_modules\@babel\runtime\helpers\asyncToGenerator.js:21:12)
    at Object.deletenote (E:\Fundoo_test\src\services\/note.service.js:26:24)
    at _callee4$ (E:\Fundoo_test\src\controllers\/note.controller.js:46:36)
    at tryCatch (E:\Fundoo_test\node_modules\@babel\runtime\helpers\regeneratorRuntime.js:86:17)
    at Generator._invoke (E:\Fundoo_test\node_modules\@babel\runtime\helpers\regeneratorRuntime.js:66:24)
    at Generator.next (E:\Fundoo_test\node_modules\@babel\runtime\helpers\regeneratorRuntime.js:117:21)
    at asyncGeneratorStep (E:\Fundoo_test\node_modules\@babel\runtime\helpers\asyncToGenerator.js:3:24)
    at _next (E:\Fundoo_test\node_modules\@babel\runtime\helpers\asyncToGenerator.js:25:9)
    at E:\Fundoo_test\node_modules\@babel\runtime\helpers\asyncToGenerator.js:32:7
    at new Promise (<anonymous>)
    at E:\Fundoo_test\node_modules\@babel\runtime\helpers\asyncToGenerator.js:21:12
    at deletenote (E:\Fundoo_test\src\controllers\/note.controller.js:44:24)
    at Layer.handle [as handle_request] (E:\Fundoo_test\node_modules\express\lib\router\layer.js:95:5)
    at next (E:\Fundoo_test\node_modules\express\lib\router\route.js:144:13)
    at _callee$ (E:\Fundoo_test\src\middlewares\/auth.middleware.js:23:5)
    at tryCatch (E:\Fundoo_test\node_modules\@babel\runtime\helpers\regeneratorRuntime.js:86:17)
    at Generator._invoke (E:\Fundoo_test\node_modules\@babel\runtime\helpers\regeneratorRuntime.js:66:24)
    at Generator.next (E:\Fundoo_test\node_modules\@babel\runtime\helpers\regeneratorRuntime.js:117:21)
    at asyncGeneratorStep (E:\Fundoo_test\node_modules\@babel\runtime\helpers\asyncToGenerator.js:3:24)
    at _next (E:\Fundoo_test\node_modules\@babel\runtime\helpers\asyncToGenerator.js:25:9)
    at processTicksAndRejections (node:internal/process/task_queues:96:5) 
    url - /api/v1/note/632c81fee6151419b497a227 
    method - DELETE 
    IP - ::1
   {"timestamp":"2022-09-22T15:41:31.709Z"}
error: 
    status - 500 
    message - ReferenceError: id is not defined
    at _callee2$ (E:\Fundoo_test\src\services\/note.service.js:10:35)
    at tryCatch (E:\Fundoo_test\node_modules\@babel\runtime\helpers\regeneratorRuntime.js:86:17)
    at Generator._invoke (E:\Fundoo_test\node_modules\@babel\runtime\helpers\regeneratorRuntime.js:66:24)
    at Generator.next (E:\Fundoo_test\node_modules\@babel\runtime\helpers\regeneratorRuntime.js:117:21)
    at asyncGeneratorStep (E:\Fundoo_test\node_modules\@babel\runtime\helpers\asyncToGenerator.js:3:24)
    at _next (E:\Fundoo_test\node_modules\@babel\runtime\helpers\asyncToGenerator.js:25:9)
    at E:\Fundoo_test\node_modules\@babel\runtime\helpers\asyncToGenerator.js:32:7
    at new Promise (<anonymous>)
    at Object.<anonymous> (E:\Fundoo_test\node_modules\@babel\runtime\helpers\asyncToGenerator.js:21:12)
    at Object.getNote (E:\Fundoo_test\src\services\/note.service.js:8:21)
    at _callee2$ (E:\Fundoo_test\src\controllers\/note.controller.js:20:36)
    at tryCatch (E:\Fundoo_test\node_modules\@babel\runtime\helpers\regeneratorRuntime.js:86:17)
    at Generator._invoke (E:\Fundoo_test\node_modules\@babel\runtime\helpers\regeneratorRuntime.js:66:24)
    at Generator.next (E:\Fundoo_test\node_modules\@babel\runtime\helpers\regeneratorRuntime.js:117:21)
    at asyncGeneratorStep (E:\Fundoo_test\node_modules\@babel\runtime\helpers\asyncToGenerator.js:3:24)
    at _next (E:\Fundoo_test\node_modules\@babel\runtime\helpers\asyncToGenerator.js:25:9)
    at E:\Fundoo_test\node_modules\@babel\runtime\helpers\asyncToGenerator.js:32:7
    at new Promise (<anonymous>)
    at E:\Fundoo_test\node_modules\@babel\runtime\helpers\asyncToGenerator.js:21:12
    at getNote (E:\Fundoo_test\src\controllers\/note.controller.js:18:21)
    at Layer.handle [as handle_request] (E:\Fundoo_test\node_modules\express\lib\router\layer.js:95:5)
    at next (E:\Fundoo_test\node_modules\express\lib\router\route.js:144:13)
    at _callee$ (E:\Fundoo_test\src\middlewares\/auth.middleware.js:23:5)
    at tryCatch (E:\Fundoo_test\node_modules\@babel\runtime\helpers\regeneratorRuntime.js:86:17)
    at Generator._invoke (E:\Fundoo_test\node_modules\@babel\runtime\helpers\regeneratorRuntime.js:66:24)
    at Generator.next (E:\Fundoo_test\node_modules\@babel\runtime\helpers\regeneratorRuntime.js:117:21)
    at asyncGeneratorStep (E:\Fundoo_test\node_modules\@babel\runtime\helpers\asyncToGenerator.js:3:24)
    at _next (E:\Fundoo_test\node_modules\@babel\runtime\helpers\asyncToGenerator.js:25:9)
    at processTicksAndRejections (node:internal/process/task_queues:96:5) 
    url - /api/v1/note/632c823ee6151419b497a229 
    method - GET 
    IP - ::1
   {"timestamp":"2022-09-22T15:42:15.420Z"}
error: 
    status - 500 
    message - ReferenceError: id is not defined
    at _callee2$ (E:\Fundoo_test\src\services\/note.service.js:10:35)
    at tryCatch (E:\Fundoo_test\node_modules\@babel\runtime\helpers\regeneratorRuntime.js:86:17)
    at Generator._invoke (E:\Fundoo_test\node_modules\@babel\runtime\helpers\regeneratorRuntime.js:66:24)
    at Generator.next (E:\Fundoo_test\node_modules\@babel\runtime\helpers\regeneratorRuntime.js:117:21)
    at asyncGeneratorStep (E:\Fundoo_test\node_modules\@babel\runtime\helpers\asyncToGenerator.js:3:24)
    at _next (E:\Fundoo_test\node_modules\@babel\runtime\helpers\asyncToGenerator.js:25:9)
    at E:\Fundoo_test\node_modules\@babel\runtime\helpers\asyncToGenerator.js:32:7
    at new Promise (<anonymous>)
    at Object.<anonymous> (E:\Fundoo_test\node_modules\@babel\runtime\helpers\asyncToGenerator.js:21:12)
    at Object.getNote (E:\Fundoo_test\src\services\/note.service.js:8:21)
    at _callee2$ (E:\Fundoo_test\src\controllers\/note.controller.js:20:36)
    at tryCatch (E:\Fundoo_test\node_modules\@babel\runtime\helpers\regeneratorRuntime.js:86:17)
    at Generator._invoke (E:\Fundoo_test\node_modules\@babel\runtime\helpers\regeneratorRuntime.js:66:24)
    at Generator.next (E:\Fundoo_test\node_modules\@babel\runtime\helpers\regeneratorRuntime.js:117:21)
    at asyncGeneratorStep (E:\Fundoo_test\node_modules\@babel\runtime\helpers\asyncToGenerator.js:3:24)
    at _next (E:\Fundoo_test\node_modules\@babel\runtime\helpers\asyncToGenerator.js:25:9)
    at E:\Fundoo_test\node_modules\@babel\runtime\helpers\asyncToGenerator.js:32:7
    at new Promise (<anonymous>)
    at E:\Fundoo_test\node_modules\@babel\runtime\helpers\asyncToGenerator.js:21:12
    at getNote (E:\Fundoo_test\src\controllers\/note.controller.js:18:21)
    at Layer.handle [as handle_request] (E:\Fundoo_test\node_modules\express\lib\router\layer.js:95:5)
    at next (E:\Fundoo_test\node_modules\express\lib\router\route.js:144:13)
    at _callee$ (E:\Fundoo_test\src\middlewares\/auth.middleware.js:23:5)
    at tryCatch (E:\Fundoo_test\node_modules\@babel\runtime\helpers\regeneratorRuntime.js:86:17)
    at Generator._invoke (E:\Fundoo_test\node_modules\@babel\runtime\helpers\regeneratorRuntime.js:66:24)
    at Generator.next (E:\Fundoo_test\node_modules\@babel\runtime\helpers\regeneratorRuntime.js:117:21)
    at asyncGeneratorStep (E:\Fundoo_test\node_modules\@babel\runtime\helpers\asyncToGenerator.js:3:24)
    at _next (E:\Fundoo_test\node_modules\@babel\runtime\helpers\asyncToGenerator.js:25:9)
    at processTicksAndRejections (node:internal/process/task_queues:96:5) 
    url - /api/v1/note/632c823ee6151419b497a229 
    method - GET 
    IP - ::1
   {"timestamp":"2022-09-22T15:43:41.851Z"}
info: Server started at http://localhost:3000/api/v1/ {"timestamp":"2022-09-22T15:45:40.662Z"}
info: Connected to the database. {"timestamp":"2022-09-22T15:45:40.715Z"}
info: Server started at http://localhost:3000/api/v1/ {"timestamp":"2022-09-22T15:45:52.670Z"}
info: Connected to the database. {"timestamp":"2022-09-22T15:45:52.744Z"}
info: Server started at http://localhost:3000/api/v1/ {"timestamp":"2022-09-22T15:49:40.975Z"}
info: Connected to the database. {"timestamp":"2022-09-22T15:49:41.001Z"}
error: 
    status - 500 
    message - ReferenceError: id is not defined
    at _callee2$ (E:\Fundoo_test\src\services\/note.service.js:10:35)
    at tryCatch (E:\Fundoo_test\node_modules\@babel\runtime\helpers\regeneratorRuntime.js:86:17)
    at Generator._invoke (E:\Fundoo_test\node_modules\@babel\runtime\helpers\regeneratorRuntime.js:66:24)
    at Generator.next (E:\Fundoo_test\node_modules\@babel\runtime\helpers\regeneratorRuntime.js:117:21)
    at asyncGeneratorStep (E:\Fundoo_test\node_modules\@babel\runtime\helpers\asyncToGenerator.js:3:24)
    at _next (E:\Fundoo_test\node_modules\@babel\runtime\helpers\asyncToGenerator.js:25:9)
    at E:\Fundoo_test\node_modules\@babel\runtime\helpers\asyncToGenerator.js:32:7
    at new Promise (<anonymous>)
    at Object.<anonymous> (E:\Fundoo_test\node_modules\@babel\runtime\helpers\asyncToGenerator.js:21:12)
    at Object.getNote (E:\Fundoo_test\src\services\/note.service.js:8:21)
    at _callee2$ (E:\Fundoo_test\src\controllers\/note.controller.js:20:36)
    at tryCatch (E:\Fundoo_test\node_modules\@babel\runtime\helpers\regeneratorRuntime.js:86:17)
    at Generator._invoke (E:\Fundoo_test\node_modules\@babel\runtime\helpers\regeneratorRuntime.js:66:24)
    at Generator.next (E:\Fundoo_test\node_modules\@babel\runtime\helpers\regeneratorRuntime.js:117:21)
    at asyncGeneratorStep (E:\Fundoo_test\node_modules\@babel\runtime\helpers\asyncToGenerator.js:3:24)
    at _next (E:\Fundoo_test\node_modules\@babel\runtime\helpers\asyncToGenerator.js:25:9)
    at E:\Fundoo_test\node_modules\@babel\runtime\helpers\asyncToGenerator.js:32:7
    at new Promise (<anonymous>)
    at E:\Fundoo_test\node_modules\@babel\runtime\helpers\asyncToGenerator.js:21:12
    at getNote (E:\Fundoo_test\src\controllers\/note.controller.js:18:21)
    at Layer.handle [as handle_request] (E:\Fundoo_test\node_modules\express\lib\router\layer.js:95:5)
    at next (E:\Fundoo_test\node_modules\express\lib\router\route.js:144:13)
    at _callee$ (E:\Fundoo_test\src\middlewares\/auth.middleware.js:23:5)
    at tryCatch (E:\Fundoo_test\node_modules\@babel\runtime\helpers\regeneratorRuntime.js:86:17)
    at Generator._invoke (E:\Fundoo_test\node_modules\@babel\runtime\helpers\regeneratorRuntime.js:66:24)
    at Generator.next (E:\Fundoo_test\node_modules\@babel\runtime\helpers\regeneratorRuntime.js:117:21)
    at asyncGeneratorStep (E:\Fundoo_test\node_modules\@babel\runtime\helpers\asyncToGenerator.js:3:24)
    at _next (E:\Fundoo_test\node_modules\@babel\runtime\helpers\asyncToGenerator.js:25:9)
    at processTicksAndRejections (node:internal/process/task_queues:96:5) 
    url - /api/v1/note/632c823ee6151419b497a229 
    method - GET 
    IP - ::1
   {"timestamp":"2022-09-22T15:49:52.601Z"}
info: Server started at http://localhost:3000/api/v1/ {"timestamp":"2022-09-22T15:51:12.042Z"}
info: Connected to the database. {"timestamp":"2022-09-22T15:51:12.123Z"}
info: Server started at http://localhost:3000/api/v1/ {"timestamp":"2022-09-22T15:51:18.768Z"}
info: Connected to the database. {"timestamp":"2022-09-22T15:51:18.795Z"}
info: Server started at http://localhost:3000/api/v1/ {"timestamp":"2022-09-22T15:51:38.136Z"}
info: Connected to the database. {"timestamp":"2022-09-22T15:51:38.280Z"}
info: Server started at http://localhost:3000/api/v1/ {"timestamp":"2022-09-22T15:51:47.015Z"}
info: Connected to the database. {"timestamp":"2022-09-22T15:51:47.064Z"}
error: 
    status - 500 
    message - ReferenceError: _id is not defined
    at _callee2$ (E:\Fundoo_test\src\services\/note.service.js:10:35)
    at tryCatch (E:\Fundoo_test\node_modules\@babel\runtime\helpers\regeneratorRuntime.js:86:17)
    at Generator._invoke (E:\Fundoo_test\node_modules\@babel\runtime\helpers\regeneratorRuntime.js:66:24)
    at Generator.next (E:\Fundoo_test\node_modules\@babel\runtime\helpers\regeneratorRuntime.js:117:21)
    at asyncGeneratorStep (E:\Fundoo_test\node_modules\@babel\runtime\helpers\asyncToGenerator.js:3:24)
    at _next (E:\Fundoo_test\node_modules\@babel\runtime\helpers\asyncToGenerator.js:25:9)
    at E:\Fundoo_test\node_modules\@babel\runtime\helpers\asyncToGenerator.js:32:7
    at new Promise (<anonymous>)
    at Object.<anonymous> (E:\Fundoo_test\node_modules\@babel\runtime\helpers\asyncToGenerator.js:21:12)
    at Object.getNote (E:\Fundoo_test\src\services\/note.service.js:8:21)
    at _callee2$ (E:\Fundoo_test\src\controllers\/note.controller.js:20:36)
    at tryCatch (E:\Fundoo_test\node_modules\@babel\runtime\helpers\regeneratorRuntime.js:86:17)
    at Generator._invoke (E:\Fundoo_test\node_modules\@babel\runtime\helpers\regeneratorRuntime.js:66:24)
    at Generator.next (E:\Fundoo_test\node_modules\@babel\runtime\helpers\regeneratorRuntime.js:117:21)
    at asyncGeneratorStep (E:\Fundoo_test\node_modules\@babel\runtime\helpers\asyncToGenerator.js:3:24)
    at _next (E:\Fundoo_test\node_modules\@babel\runtime\helpers\asyncToGenerator.js:25:9)
    at E:\Fundoo_test\node_modules\@babel\runtime\helpers\asyncToGenerator.js:32:7
    at new Promise (<anonymous>)
    at E:\Fundoo_test\node_modules\@babel\runtime\helpers\asyncToGenerator.js:21:12
    at getNote (E:\Fundoo_test\src\controllers\/note.controller.js:18:21)
    at Layer.handle [as handle_request] (E:\Fundoo_test\node_modules\express\lib\router\layer.js:95:5)
    at next (E:\Fundoo_test\node_modules\express\lib\router\route.js:144:13)
    at _callee$ (E:\Fundoo_test\src\middlewares\/auth.middleware.js:23:5)
    at tryCatch (E:\Fundoo_test\node_modules\@babel\runtime\helpers\regeneratorRuntime.js:86:17)
    at Generator._invoke (E:\Fundoo_test\node_modules\@babel\runtime\helpers\regeneratorRuntime.js:66:24)
    at Generator.next (E:\Fundoo_test\node_modules\@babel\runtime\helpers\regeneratorRuntime.js:117:21)
    at asyncGeneratorStep (E:\Fundoo_test\node_modules\@babel\runtime\helpers\asyncToGenerator.js:3:24)
    at _next (E:\Fundoo_test\node_modules\@babel\runtime\helpers\asyncToGenerator.js:25:9)
    at processTicksAndRejections (node:internal/process/task_queues:96:5) 
    url - /api/v1/note/632c823ee6151419b497a229 
    method - GET 
    IP - ::1
   {"timestamp":"2022-09-22T15:52:05.086Z"}
error: 
    status - 500 
    message - ReferenceError: body is not defined
    at _callee4$ (E:\Fundoo_test\src\services\/note.service.js:27:15)
    at tryCatch (E:\Fundoo_test\node_modules\@babel\runtime\helpers\regeneratorRuntime.js:86:17)
    at Generator._invoke (E:\Fundoo_test\node_modules\@babel\runtime\helpers\regeneratorRuntime.js:66:24)
    at Generator.next (E:\Fundoo_test\node_modules\@babel\runtime\helpers\regeneratorRuntime.js:117:21)
    at asyncGeneratorStep (E:\Fundoo_test\node_modules\@babel\runtime\helpers\asyncToGenerator.js:3:24)
    at _next (E:\Fundoo_test\node_modules\@babel\runtime\helpers\asyncToGenerator.js:25:9)
    at E:\Fundoo_test\node_modules\@babel\runtime\helpers\asyncToGenerator.js:32:7
    at new Promise (<anonymous>)
    at Object.<anonymous> (E:\Fundoo_test\node_modules\@babel\runtime\helpers\asyncToGenerator.js:21:12)
    at Object.deletenote (E:\Fundoo_test\src\services\/note.service.js:26:24)
    at _callee4$ (E:\Fundoo_test\src\controllers\/note.controller.js:46:36)
    at tryCatch (E:\Fundoo_test\node_modules\@babel\runtime\helpers\regeneratorRuntime.js:86:17)
    at Generator._invoke (E:\Fundoo_test\node_modules\@babel\runtime\helpers\regeneratorRuntime.js:66:24)
    at Generator.next (E:\Fundoo_test\node_modules\@babel\runtime\helpers\regeneratorRuntime.js:117:21)
    at asyncGeneratorStep (E:\Fundoo_test\node_modules\@babel\runtime\helpers\asyncToGenerator.js:3:24)
    at _next (E:\Fundoo_test\node_modules\@babel\runtime\helpers\asyncToGenerator.js:25:9)
    at E:\Fundoo_test\node_modules\@babel\runtime\helpers\asyncToGenerator.js:32:7
    at new Promise (<anonymous>)
    at E:\Fundoo_test\node_modules\@babel\runtime\helpers\asyncToGenerator.js:21:12
    at deletenote (E:\Fundoo_test\src\controllers\/note.controller.js:44:24)
    at Layer.handle [as handle_request] (E:\Fundoo_test\node_modules\express\lib\router\layer.js:95:5)
    at next (E:\Fundoo_test\node_modules\express\lib\router\route.js:144:13)
    at _callee$ (E:\Fundoo_test\src\middlewares\/auth.middleware.js:23:5)
    at tryCatch (E:\Fundoo_test\node_modules\@babel\runtime\helpers\regeneratorRuntime.js:86:17)
    at Generator._invoke (E:\Fundoo_test\node_modules\@babel\runtime\helpers\regeneratorRuntime.js:66:24)
    at Generator.next (E:\Fundoo_test\node_modules\@babel\runtime\helpers\regeneratorRuntime.js:117:21)
    at asyncGeneratorStep (E:\Fundoo_test\node_modules\@babel\runtime\helpers\asyncToGenerator.js:3:24)
    at _next (E:\Fundoo_test\node_modules\@babel\runtime\helpers\asyncToGenerator.js:25:9)
    at processTicksAndRejections (node:internal/process/task_queues:96:5) 
    url - /api/v1/note/632c84bc147d842e209ca447 
    method - DELETE 
    IP - ::1
   {"timestamp":"2022-09-22T15:53:05.437Z"}
info: Server started at http://localhost:3000/api/v1/ {"timestamp":"2022-09-22T15:53:44.425Z"}
info: Connected to the database. {"timestamp":"2022-09-22T15:53:44.479Z"}
error: 
    status - 500 
    message - ReferenceError: _id is not defined
    at _callee2$ (E:\Fundoo_test\src\services\/note.service.js:10:35)
    at tryCatch (E:\Fundoo_test\node_modules\@babel\runtime\helpers\regeneratorRuntime.js:86:17)
    at Generator._invoke (E:\Fundoo_test\node_modules\@babel\runtime\helpers\regeneratorRuntime.js:66:24)
    at Generator.next (E:\Fundoo_test\node_modules\@babel\runtime\helpers\regeneratorRuntime.js:117:21)
    at asyncGeneratorStep (E:\Fundoo_test\node_modules\@babel\runtime\helpers\asyncToGenerator.js:3:24)
    at _next (E:\Fundoo_test\node_modules\@babel\runtime\helpers\asyncToGenerator.js:25:9)
    at E:\Fundoo_test\node_modules\@babel\runtime\helpers\asyncToGenerator.js:32:7
    at new Promise (<anonymous>)
    at Object.<anonymous> (E:\Fundoo_test\node_modules\@babel\runtime\helpers\asyncToGenerator.js:21:12)
    at Object.getNote (E:\Fundoo_test\src\services\/note.service.js:8:21)
    at _callee2$ (E:\Fundoo_test\src\controllers\/note.controller.js:20:36)
    at tryCatch (E:\Fundoo_test\node_modules\@babel\runtime\helpers\regeneratorRuntime.js:86:17)
    at Generator._invoke (E:\Fundoo_test\node_modules\@babel\runtime\helpers\regeneratorRuntime.js:66:24)
    at Generator.next (E:\Fundoo_test\node_modules\@babel\runtime\helpers\regeneratorRuntime.js:117:21)
    at asyncGeneratorStep (E:\Fundoo_test\node_modules\@babel\runtime\helpers\asyncToGenerator.js:3:24)
    at _next (E:\Fundoo_test\node_modules\@babel\runtime\helpers\asyncToGenerator.js:25:9)
    at E:\Fundoo_test\node_modules\@babel\runtime\helpers\asyncToGenerator.js:32:7
    at new Promise (<anonymous>)
    at E:\Fundoo_test\node_modules\@babel\runtime\helpers\asyncToGenerator.js:21:12
    at getNote (E:\Fundoo_test\src\controllers\/note.controller.js:18:21)
    at Layer.handle [as handle_request] (E:\Fundoo_test\node_modules\express\lib\router\layer.js:95:5)
    at next (E:\Fundoo_test\node_modules\express\lib\router\route.js:144:13)
    at _callee$ (E:\Fundoo_test\src\middlewares\/auth.middleware.js:23:5)
    at tryCatch (E:\Fundoo_test\node_modules\@babel\runtime\helpers\regeneratorRuntime.js:86:17)
    at Generator._invoke (E:\Fundoo_test\node_modules\@babel\runtime\helpers\regeneratorRuntime.js:66:24)
    at Generator.next (E:\Fundoo_test\node_modules\@babel\runtime\helpers\regeneratorRuntime.js:117:21)
    at asyncGeneratorStep (E:\Fundoo_test\node_modules\@babel\runtime\helpers\asyncToGenerator.js:3:24)
    at _next (E:\Fundoo_test\node_modules\@babel\runtime\helpers\asyncToGenerator.js:25:9)
    at processTicksAndRejections (node:internal/process/task_queues:96:5) 
    url - /api/v1/note/632c84bc147d842e209ca447 
    method - GET 
    IP - ::1
   {"timestamp":"2022-09-22T15:53:58.924Z"}
error: 
    status - 500 
    message - CastError: Cast to ObjectId failed for value "{ _id: undefined }" (type Object) at path "_id" for model "Note"
    at model.Query.exec (E:\Fundoo_test\node_modules\mongoose\lib\query.js:4498:21)
    at model.Query.Query.then (E:\Fundoo_test\node_modules\mongoose\lib\query.js:4592:15)
    at processTicksAndRejections (node:internal/process/task_queues:96:5) 
    url - /api/v1/note/632c85352238172790e2fef9 
    method - PUT 
    IP - ::1
   {"timestamp":"2022-09-22T15:54:54.294Z"}
info: Server started at http://localhost:3000/api/v1/ {"timestamp":"2022-09-22T15:56:26.799Z"}
info: Connected to the database. {"timestamp":"2022-09-22T15:56:26.903Z"}
info: Server started at http://localhost:3000/api/v1/ {"timestamp":"2022-09-22T15:57:17.387Z"}
info: Connected to the database. {"timestamp":"2022-09-22T15:57:17.509Z"}
error: 
    status - 500 
    message - CastError: Cast to ObjectId failed for value "{ _id: undefined }" (type Object) at path "_id" for model "Note"
    at model.Query.exec (E:\Fundoo_test\node_modules\mongoose\lib\query.js:4498:21)
    at model.Query.Query.then (E:\Fundoo_test\node_modules\mongoose\lib\query.js:4592:15)
    at processTicksAndRejections (node:internal/process/task_queues:96:5) 
    url - /api/v1/note/632c85352238172790e2fef9 
    method - PUT 
    IP - ::1
   {"timestamp":"2022-09-22T15:57:19.257Z"}
info: Server started at http://localhost:3000/api/v1/ {"timestamp":"2022-09-22T15:57:53.282Z"}
info: Connected to the database. {"timestamp":"2022-09-22T15:57:53.314Z"}
error: 
    status - 500 
    message - CastError: Cast to ObjectId failed for value "{ _id: undefined }" (type Object) at path "_id" for model "Note"
    at model.Query.exec (E:\Fundoo_test\node_modules\mongoose\lib\query.js:4498:21)
    at model.Query.Query.then (E:\Fundoo_test\node_modules\mongoose\lib\query.js:4592:15)
    at processTicksAndRejections (node:internal/process/task_queues:96:5) 
    url - /api/v1/note/632c85352238172790e2fef9 
    method - PUT 
    IP - ::1
   {"timestamp":"2022-09-22T15:58:10.373Z"}
error: 
    status - 500 
    message - ReferenceError: _id is not defined
    at _callee2$ (E:\Fundoo_test\src\services\/note.service.js:10:35)
    at tryCatch (E:\Fundoo_test\node_modules\@babel\runtime\helpers\regeneratorRuntime.js:86:17)
    at Generator._invoke (E:\Fundoo_test\node_modules\@babel\runtime\helpers\regeneratorRuntime.js:66:24)
    at Generator.next (E:\Fundoo_test\node_modules\@babel\runtime\helpers\regeneratorRuntime.js:117:21)
    at asyncGeneratorStep (E:\Fundoo_test\node_modules\@babel\runtime\helpers\asyncToGenerator.js:3:24)
    at _next (E:\Fundoo_test\node_modules\@babel\runtime\helpers\asyncToGenerator.js:25:9)
    at E:\Fundoo_test\node_modules\@babel\runtime\helpers\asyncToGenerator.js:32:7
    at new Promise (<anonymous>)
    at Object.<anonymous> (E:\Fundoo_test\node_modules\@babel\runtime\helpers\asyncToGenerator.js:21:12)
    at Object.getNote (E:\Fundoo_test\src\services\/note.service.js:8:21)
    at _callee2$ (E:\Fundoo_test\src\controllers\/note.controller.js:20:36)
    at tryCatch (E:\Fundoo_test\node_modules\@babel\runtime\helpers\regeneratorRuntime.js:86:17)
    at Generator._invoke (E:\Fundoo_test\node_modules\@babel\runtime\helpers\regeneratorRuntime.js:66:24)
    at Generator.next (E:\Fundoo_test\node_modules\@babel\runtime\helpers\regeneratorRuntime.js:117:21)
    at asyncGeneratorStep (E:\Fundoo_test\node_modules\@babel\runtime\helpers\asyncToGenerator.js:3:24)
    at _next (E:\Fundoo_test\node_modules\@babel\runtime\helpers\asyncToGenerator.js:25:9)
    at E:\Fundoo_test\node_modules\@babel\runtime\helpers\asyncToGenerator.js:32:7
    at new Promise (<anonymous>)
    at E:\Fundoo_test\node_modules\@babel\runtime\helpers\asyncToGenerator.js:21:12
    at getNote (E:\Fundoo_test\src\controllers\/note.controller.js:18:21)
    at Layer.handle [as handle_request] (E:\Fundoo_test\node_modules\express\lib\router\layer.js:95:5)
    at next (E:\Fundoo_test\node_modules\express\lib\router\route.js:144:13)
    at _callee$ (E:\Fundoo_test\src\middlewares\/auth.middleware.js:23:5)
    at tryCatch (E:\Fundoo_test\node_modules\@babel\runtime\helpers\regeneratorRuntime.js:86:17)
    at Generator._invoke (E:\Fundoo_test\node_modules\@babel\runtime\helpers\regeneratorRuntime.js:66:24)
    at Generator.next (E:\Fundoo_test\node_modules\@babel\runtime\helpers\regeneratorRuntime.js:117:21)
    at asyncGeneratorStep (E:\Fundoo_test\node_modules\@babel\runtime\helpers\asyncToGenerator.js:3:24)
    at _next (E:\Fundoo_test\node_modules\@babel\runtime\helpers\asyncToGenerator.js:25:9)
    at processTicksAndRejections (node:internal/process/task_queues:96:5) 
    url - /api/v1/note/632c85352238172790e2fef9 
    method - GET 
    IP - ::1
   {"timestamp":"2022-09-22T15:58:16.479Z"}
info: Server started at http://localhost:3000/api/v1/ {"timestamp":"2022-09-22T15:59:48.083Z"}
info: Connected to the database. {"timestamp":"2022-09-22T15:59:48.141Z"}
info: Server started at http://localhost:3000/api/v1/ {"timestamp":"2022-09-22T16:07:43.933Z"}
info: Connected to the database. {"timestamp":"2022-09-22T16:07:43.978Z"}
error: 
    status - 500 
    message - ReferenceError: body is not defined
    at _callee6$ (E:\Fundoo_test\src\services\/note.service.js:37:15)
    at tryCatch (E:\Fundoo_test\node_modules\@babel\runtime\helpers\regeneratorRuntime.js:86:17)
    at Generator._invoke (E:\Fundoo_test\node_modules\@babel\runtime\helpers\regeneratorRuntime.js:66:24)
    at Generator.next (E:\Fundoo_test\node_modules\@babel\runtime\helpers\regeneratorRuntime.js:117:21)
    at asyncGeneratorStep (E:\Fundoo_test\node_modules\@babel\runtime\helpers\asyncToGenerator.js:3:24)
    at _next (E:\Fundoo_test\node_modules\@babel\runtime\helpers\asyncToGenerator.js:25:9)
    at E:\Fundoo_test\node_modules\@babel\runtime\helpers\asyncToGenerator.js:32:7
    at new Promise (<anonymous>)
    at Object.<anonymous> (E:\Fundoo_test\node_modules\@babel\runtime\helpers\asyncToGenerator.js:21:12)
    at Object.archiveNote (E:\Fundoo_test\src\services\/note.service.js:36:25)
    at _callee6$ (E:\Fundoo_test\src\controllers\/note.controller.js:70:36)
    at tryCatch (E:\Fundoo_test\node_modules\@babel\runtime\helpers\regeneratorRuntime.js:86:17)
    at Generator._invoke (E:\Fundoo_test\node_modules\@babel\runtime\helpers\regeneratorRuntime.js:66:24)
    at Generator.next (E:\Fundoo_test\node_modules\@babel\runtime\helpers\regeneratorRuntime.js:117:21)
    at asyncGeneratorStep (E:\Fundoo_test\node_modules\@babel\runtime\helpers\asyncToGenerator.js:3:24)
    at _next (E:\Fundoo_test\node_modules\@babel\runtime\helpers\asyncToGenerator.js:25:9)
    at E:\Fundoo_test\node_modules\@babel\runtime\helpers\asyncToGenerator.js:32:7
    at new Promise (<anonymous>)
    at E:\Fundoo_test\node_modules\@babel\runtime\helpers\asyncToGenerator.js:21:12
    at archiveNote (E:\Fundoo_test\src\controllers\/note.controller.js:68:25)
    at Layer.handle [as handle_request] (E:\Fundoo_test\node_modules\express\lib\router\layer.js:95:5)
    at next (E:\Fundoo_test\node_modules\express\lib\router\route.js:144:13)
    at _callee$ (E:\Fundoo_test\src\middlewares\/auth.middleware.js:23:5)
    at tryCatch (E:\Fundoo_test\node_modules\@babel\runtime\helpers\regeneratorRuntime.js:86:17)
    at Generator._invoke (E:\Fundoo_test\node_modules\@babel\runtime\helpers\regeneratorRuntime.js:66:24)
    at Generator.next (E:\Fundoo_test\node_modules\@babel\runtime\helpers\regeneratorRuntime.js:117:21)
    at asyncGeneratorStep (E:\Fundoo_test\node_modules\@babel\runtime\helpers\asyncToGenerator.js:3:24)
    at _next (E:\Fundoo_test\node_modules\@babel\runtime\helpers\asyncToGenerator.js:25:9)
    at processTicksAndRejections (node:internal/process/task_queues:96:5) 
    url - /api/v1/note/isarchive/632c85352238172790e2fef9 
    method - PUT 
    IP - ::1
   {"timestamp":"2022-09-22T16:21:28.592Z"}
info: Server started at http://localhost:3000/api/v1/ {"timestamp":"2022-09-22T16:27:28.291Z"}
info: Connected to the database. {"timestamp":"2022-09-22T16:27:28.373Z"}
error: 
    status - 500 
    message - ReferenceError: body is not defined
    at _callee6$ (E:\Fundoo_test\src\services\/note.service.js:37:15)
    at tryCatch (E:\Fundoo_test\node_modules\@babel\runtime\helpers\regeneratorRuntime.js:86:17)
    at Generator._invoke (E:\Fundoo_test\node_modules\@babel\runtime\helpers\regeneratorRuntime.js:66:24)
    at Generator.next (E:\Fundoo_test\node_modules\@babel\runtime\helpers\regeneratorRuntime.js:117:21)
    at asyncGeneratorStep (E:\Fundoo_test\node_modules\@babel\runtime\helpers\asyncToGenerator.js:3:24)
    at _next (E:\Fundoo_test\node_modules\@babel\runtime\helpers\asyncToGenerator.js:25:9)
    at E:\Fundoo_test\node_modules\@babel\runtime\helpers\asyncToGenerator.js:32:7
    at new Promise (<anonymous>)
    at Object.<anonymous> (E:\Fundoo_test\node_modules\@babel\runtime\helpers\asyncToGenerator.js:21:12)
    at Object.archiveNote (E:\Fundoo_test\src\services\/note.service.js:36:25)
    at _callee6$ (E:\Fundoo_test\src\controllers\/note.controller.js:70:36)
    at tryCatch (E:\Fundoo_test\node_modules\@babel\runtime\helpers\regeneratorRuntime.js:86:17)
    at Generator._invoke (E:\Fundoo_test\node_modules\@babel\runtime\helpers\regeneratorRuntime.js:66:24)
    at Generator.next (E:\Fundoo_test\node_modules\@babel\runtime\helpers\regeneratorRuntime.js:117:21)
    at asyncGeneratorStep (E:\Fundoo_test\node_modules\@babel\runtime\helpers\asyncToGenerator.js:3:24)
    at _next (E:\Fundoo_test\node_modules\@babel\runtime\helpers\asyncToGenerator.js:25:9)
    at E:\Fundoo_test\node_modules\@babel\runtime\helpers\asyncToGenerator.js:32:7
    at new Promise (<anonymous>)
    at E:\Fundoo_test\node_modules\@babel\runtime\helpers\asyncToGenerator.js:21:12
    at archiveNote (E:\Fundoo_test\src\controllers\/note.controller.js:68:25)
    at Layer.handle [as handle_request] (E:\Fundoo_test\node_modules\express\lib\router\layer.js:95:5)
    at next (E:\Fundoo_test\node_modules\express\lib\router\route.js:144:13)
    at _callee$ (E:\Fundoo_test\src\middlewares\/auth.middleware.js:23:5)
    at tryCatch (E:\Fundoo_test\node_modules\@babel\runtime\helpers\regeneratorRuntime.js:86:17)
    at Generator._invoke (E:\Fundoo_test\node_modules\@babel\runtime\helpers\regeneratorRuntime.js:66:24)
    at Generator.next (E:\Fundoo_test\node_modules\@babel\runtime\helpers\regeneratorRuntime.js:117:21)
    at asyncGeneratorStep (E:\Fundoo_test\node_modules\@babel\runtime\helpers\asyncToGenerator.js:3:24)
    at _next (E:\Fundoo_test\node_modules\@babel\runtime\helpers\asyncToGenerator.js:25:9)
    at processTicksAndRejections (node:internal/process/task_queues:96:5) 
    url - /api/v1/note/isarchive/632c85352238172790e2fef9 
    method - PUT 
    IP - ::1
   {"timestamp":"2022-09-22T16:27:47.035Z"}
info: Server started at http://localhost:3000/api/v1/ {"timestamp":"2022-09-22T16:28:26.158Z"}
info: Connected to the database. {"timestamp":"2022-09-22T16:28:26.461Z"}
info: Server started at http://localhost:3000/api/v1/ {"timestamp":"2022-09-22T16:28:36.129Z"}
info: Connected to the database. {"timestamp":"2022-09-22T16:28:36.172Z"}
info: Server started at http://localhost:3000/api/v1/ {"timestamp":"2022-09-22T16:28:59.154Z"}
info: Connected to the database. {"timestamp":"2022-09-22T16:28:59.192Z"}
info: Server started at http://localhost:3000/api/v1/ {"timestamp":"2022-09-22T16:29:09.640Z"}
info: Connected to the database. {"timestamp":"2022-09-22T16:29:09.744Z"}
info: Server started at http://localhost:3000/api/v1/ {"timestamp":"2022-09-22T16:29:22.951Z"}
info: Connected to the database. {"timestamp":"2022-09-22T16:29:22.986Z"}
info: Server started at http://localhost:3000/api/v1/ {"timestamp":"2022-09-22T16:29:38.742Z"}
info: Connected to the database. {"timestamp":"2022-09-22T16:29:38.830Z"}
error: 
    status - 500 
    message - MongooseError: Callback must be a function, got [object Object]
    at Function.Model.$handleCallbackError (E:\Fundoo_test\node_modules\mongoose\lib\model.js:5067:11)
    at Function.findByIdAndUpdate (E:\Fundoo_test\node_modules\mongoose\lib\model.js:2694:19)
    at _callee6$ (E:\Fundoo_test\src\services\/note.service.js:38:27)
    at tryCatch (E:\Fundoo_test\node_modules\@babel\runtime\helpers\regeneratorRuntime.js:86:17)
    at Generator._invoke (E:\Fundoo_test\node_modules\@babel\runtime\helpers\regeneratorRuntime.js:66:24)
    at Generator.next (E:\Fundoo_test\node_modules\@babel\runtime\helpers\regeneratorRuntime.js:117:21)
    at asyncGeneratorStep (E:\Fundoo_test\node_modules\@babel\runtime\helpers\asyncToGenerator.js:3:24)
    at _next (E:\Fundoo_test\node_modules\@babel\runtime\helpers\asyncToGenerator.js:25:9)
    at E:\Fundoo_test\node_modules\@babel\runtime\helpers\asyncToGenerator.js:32:7
    at new Promise (<anonymous>)
    at Object.<anonymous> (E:\Fundoo_test\node_modules\@babel\runtime\helpers\asyncToGenerator.js:21:12)
    at Object.archiveNote (E:\Fundoo_test\src\services\/note.service.js:36:25)
    at _callee6$ (E:\Fundoo_test\src\controllers\/note.controller.js:70:36)
    at tryCatch (E:\Fundoo_test\node_modules\@babel\runtime\helpers\regeneratorRuntime.js:86:17)
    at Generator._invoke (E:\Fundoo_test\node_modules\@babel\runtime\helpers\regeneratorRuntime.js:66:24)
    at Generator.next (E:\Fundoo_test\node_modules\@babel\runtime\helpers\regeneratorRuntime.js:117:21)
    at asyncGeneratorStep (E:\Fundoo_test\node_modules\@babel\runtime\helpers\asyncToGenerator.js:3:24)
    at _next (E:\Fundoo_test\node_modules\@babel\runtime\helpers\asyncToGenerator.js:25:9)
    at E:\Fundoo_test\node_modules\@babel\runtime\helpers\asyncToGenerator.js:32:7
    at new Promise (<anonymous>)
    at E:\Fundoo_test\node_modules\@babel\runtime\helpers\asyncToGenerator.js:21:12
    at archiveNote (E:\Fundoo_test\src\controllers\/note.controller.js:68:25)
    at Layer.handle [as handle_request] (E:\Fundoo_test\node_modules\express\lib\router\layer.js:95:5)
    at next (E:\Fundoo_test\node_modules\express\lib\router\route.js:144:13)
    at _callee$ (E:\Fundoo_test\src\middlewares\/auth.middleware.js:23:5)
    at tryCatch (E:\Fundoo_test\node_modules\@babel\runtime\helpers\regeneratorRuntime.js:86:17)
    at Generator._invoke (E:\Fundoo_test\node_modules\@babel\runtime\helpers\regeneratorRuntime.js:66:24)
    at Generator.next (E:\Fundoo_test\node_modules\@babel\runtime\helpers\regeneratorRuntime.js:117:21)
    at asyncGeneratorStep (E:\Fundoo_test\node_modules\@babel\runtime\helpers\asyncToGenerator.js:3:24)
    at _next (E:\Fundoo_test\node_modules\@babel\runtime\helpers\asyncToGenerator.js:25:9)
    at processTicksAndRejections (node:internal/process/task_queues:96:5) 
    url - /api/v1/note/isarchive/632c85352238172790e2fef9 
    method - PUT 
    IP - ::1
   {"timestamp":"2022-09-22T16:29:40.302Z"}
info: Server started at http://localhost:3000/api/v1/ {"timestamp":"2022-09-22T16:30:40.500Z"}
info: Connected to the database. {"timestamp":"2022-09-22T16:30:40.601Z"}
error: 
    status - 500 
    message - MongooseError: Callback must be a function, got [object Object]
    at Function.Model.$handleCallbackError (E:\Fundoo_test\node_modules\mongoose\lib\model.js:5067:11)
    at Function.findByIdAndUpdate (E:\Fundoo_test\node_modules\mongoose\lib\model.js:2694:19)
    at _callee6$ (E:\Fundoo_test\src\services\/note.service.js:38:27)
    at tryCatch (E:\Fundoo_test\node_modules\@babel\runtime\helpers\regeneratorRuntime.js:86:17)
    at Generator._invoke (E:\Fundoo_test\node_modules\@babel\runtime\helpers\regeneratorRuntime.js:66:24)
    at Generator.next (E:\Fundoo_test\node_modules\@babel\runtime\helpers\regeneratorRuntime.js:117:21)
    at asyncGeneratorStep (E:\Fundoo_test\node_modules\@babel\runtime\helpers\asyncToGenerator.js:3:24)
    at _next (E:\Fundoo_test\node_modules\@babel\runtime\helpers\asyncToGenerator.js:25:9)
    at E:\Fundoo_test\node_modules\@babel\runtime\helpers\asyncToGenerator.js:32:7
    at new Promise (<anonymous>)
    at Object.<anonymous> (E:\Fundoo_test\node_modules\@babel\runtime\helpers\asyncToGenerator.js:21:12)
    at Object.archiveNote (E:\Fundoo_test\src\services\/note.service.js:36:25)
    at _callee6$ (E:\Fundoo_test\src\controllers\/note.controller.js:70:36)
    at tryCatch (E:\Fundoo_test\node_modules\@babel\runtime\helpers\regeneratorRuntime.js:86:17)
    at Generator._invoke (E:\Fundoo_test\node_modules\@babel\runtime\helpers\regeneratorRuntime.js:66:24)
    at Generator.next (E:\Fundoo_test\node_modules\@babel\runtime\helpers\regeneratorRuntime.js:117:21)
    at asyncGeneratorStep (E:\Fundoo_test\node_modules\@babel\runtime\helpers\asyncToGenerator.js:3:24)
    at _next (E:\Fundoo_test\node_modules\@babel\runtime\helpers\asyncToGenerator.js:25:9)
    at E:\Fundoo_test\node_modules\@babel\runtime\helpers\asyncToGenerator.js:32:7
    at new Promise (<anonymous>)
    at E:\Fundoo_test\node_modules\@babel\runtime\helpers\asyncToGenerator.js:21:12
    at archiveNote (E:\Fundoo_test\src\controllers\/note.controller.js:68:25)
    at Layer.handle [as handle_request] (E:\Fundoo_test\node_modules\express\lib\router\layer.js:95:5)
    at next (E:\Fundoo_test\node_modules\express\lib\router\route.js:144:13)
    at _callee$ (E:\Fundoo_test\src\middlewares\/auth.middleware.js:23:5)
    at tryCatch (E:\Fundoo_test\node_modules\@babel\runtime\helpers\regeneratorRuntime.js:86:17)
    at Generator._invoke (E:\Fundoo_test\node_modules\@babel\runtime\helpers\regeneratorRuntime.js:66:24)
    at Generator.next (E:\Fundoo_test\node_modules\@babel\runtime\helpers\regeneratorRuntime.js:117:21)
    at asyncGeneratorStep (E:\Fundoo_test\node_modules\@babel\runtime\helpers\asyncToGenerator.js:3:24)
    at _next (E:\Fundoo_test\node_modules\@babel\runtime\helpers\asyncToGenerator.js:25:9)
    at processTicksAndRejections (node:internal/process/task_queues:96:5) 
    url - /api/v1/note/isarchive/632c85352238172790e2fef9 
    method - PUT 
    IP - ::1
   {"timestamp":"2022-09-22T16:30:41.988Z"}
error: 
    status - 500 
    message - MongooseError: Callback must be a function, got [object Object]
    at Function.Model.$handleCallbackError (E:\Fundoo_test\node_modules\mongoose\lib\model.js:5067:11)
    at Function.findByIdAndUpdate (E:\Fundoo_test\node_modules\mongoose\lib\model.js:2694:19)
    at _callee6$ (E:\Fundoo_test\src\services\/note.service.js:38:27)
    at tryCatch (E:\Fundoo_test\node_modules\@babel\runtime\helpers\regeneratorRuntime.js:86:17)
    at Generator._invoke (E:\Fundoo_test\node_modules\@babel\runtime\helpers\regeneratorRuntime.js:66:24)
    at Generator.next (E:\Fundoo_test\node_modules\@babel\runtime\helpers\regeneratorRuntime.js:117:21)
    at asyncGeneratorStep (E:\Fundoo_test\node_modules\@babel\runtime\helpers\asyncToGenerator.js:3:24)
    at _next (E:\Fundoo_test\node_modules\@babel\runtime\helpers\asyncToGenerator.js:25:9)
    at E:\Fundoo_test\node_modules\@babel\runtime\helpers\asyncToGenerator.js:32:7
    at new Promise (<anonymous>)
    at Object.<anonymous> (E:\Fundoo_test\node_modules\@babel\runtime\helpers\asyncToGenerator.js:21:12)
    at Object.archiveNote (E:\Fundoo_test\src\services\/note.service.js:36:25)
    at _callee6$ (E:\Fundoo_test\src\controllers\/note.controller.js:70:36)
    at tryCatch (E:\Fundoo_test\node_modules\@babel\runtime\helpers\regeneratorRuntime.js:86:17)
    at Generator._invoke (E:\Fundoo_test\node_modules\@babel\runtime\helpers\regeneratorRuntime.js:66:24)
    at Generator.next (E:\Fundoo_test\node_modules\@babel\runtime\helpers\regeneratorRuntime.js:117:21)
    at asyncGeneratorStep (E:\Fundoo_test\node_modules\@babel\runtime\helpers\asyncToGenerator.js:3:24)
    at _next (E:\Fundoo_test\node_modules\@babel\runtime\helpers\asyncToGenerator.js:25:9)
    at E:\Fundoo_test\node_modules\@babel\runtime\helpers\asyncToGenerator.js:32:7
    at new Promise (<anonymous>)
    at E:\Fundoo_test\node_modules\@babel\runtime\helpers\asyncToGenerator.js:21:12
    at archiveNote (E:\Fundoo_test\src\controllers\/note.controller.js:68:25)
    at Layer.handle [as handle_request] (E:\Fundoo_test\node_modules\express\lib\router\layer.js:95:5)
    at next (E:\Fundoo_test\node_modules\express\lib\router\route.js:144:13)
    at _callee$ (E:\Fundoo_test\src\middlewares\/auth.middleware.js:23:5)
    at tryCatch (E:\Fundoo_test\node_modules\@babel\runtime\helpers\regeneratorRuntime.js:86:17)
    at Generator._invoke (E:\Fundoo_test\node_modules\@babel\runtime\helpers\regeneratorRuntime.js:66:24)
    at Generator.next (E:\Fundoo_test\node_modules\@babel\runtime\helpers\regeneratorRuntime.js:117:21)
    at asyncGeneratorStep (E:\Fundoo_test\node_modules\@babel\runtime\helpers\asyncToGenerator.js:3:24)
    at _next (E:\Fundoo_test\node_modules\@babel\runtime\helpers\asyncToGenerator.js:25:9)
    at processTicksAndRejections (node:internal/process/task_queues:96:5) 
    url - /api/v1/note/isarchive/632c85352238172790e2fef9 
    method - PUT 
    IP - ::1
   {"timestamp":"2022-09-22T16:31:08.650Z"}
info: Server started at http://localhost:3000/api/v1/ {"timestamp":"2022-09-22T16:38:26.152Z"}
info: Connected to the database. {"timestamp":"2022-09-22T16:38:26.200Z"}
info: Server started at http://localhost:3000/api/v1/ {"timestamp":"2022-09-22T16:38:34.150Z"}
info: Connected to the database. {"timestamp":"2022-09-22T16:38:34.205Z"}
error: 
    status - 500 
    message - ReferenceError: body is not defined
    at _callee6$ (E:\Fundoo_test\src\services\/note.service.js:37:15)
    at tryCatch (E:\Fundoo_test\node_modules\@babel\runtime\helpers\regeneratorRuntime.js:86:17)
    at Generator._invoke (E:\Fundoo_test\node_modules\@babel\runtime\helpers\regeneratorRuntime.js:66:24)
    at Generator.next (E:\Fundoo_test\node_modules\@babel\runtime\helpers\regeneratorRuntime.js:117:21)
    at asyncGeneratorStep (E:\Fundoo_test\node_modules\@babel\runtime\helpers\asyncToGenerator.js:3:24)
    at _next (E:\Fundoo_test\node_modules\@babel\runtime\helpers\asyncToGenerator.js:25:9)
    at E:\Fundoo_test\node_modules\@babel\runtime\helpers\asyncToGenerator.js:32:7
    at new Promise (<anonymous>)
    at Object.<anonymous> (E:\Fundoo_test\node_modules\@babel\runtime\helpers\asyncToGenerator.js:21:12)
    at Object.archiveNote (E:\Fundoo_test\src\services\/note.service.js:36:25)
    at _callee6$ (E:\Fundoo_test\src\controllers\/note.controller.js:70:36)
    at tryCatch (E:\Fundoo_test\node_modules\@babel\runtime\helpers\regeneratorRuntime.js:86:17)
    at Generator._invoke (E:\Fundoo_test\node_modules\@babel\runtime\helpers\regeneratorRuntime.js:66:24)
    at Generator.next (E:\Fundoo_test\node_modules\@babel\runtime\helpers\regeneratorRuntime.js:117:21)
    at asyncGeneratorStep (E:\Fundoo_test\node_modules\@babel\runtime\helpers\asyncToGenerator.js:3:24)
    at _next (E:\Fundoo_test\node_modules\@babel\runtime\helpers\asyncToGenerator.js:25:9)
    at E:\Fundoo_test\node_modules\@babel\runtime\helpers\asyncToGenerator.js:32:7
    at new Promise (<anonymous>)
    at E:\Fundoo_test\node_modules\@babel\runtime\helpers\asyncToGenerator.js:21:12
    at archiveNote (E:\Fundoo_test\src\controllers\/note.controller.js:68:25)
    at Layer.handle [as handle_request] (E:\Fundoo_test\node_modules\express\lib\router\layer.js:95:5)
    at next (E:\Fundoo_test\node_modules\express\lib\router\route.js:144:13)
    at _callee$ (E:\Fundoo_test\src\middlewares\/auth.middleware.js:23:5)
    at tryCatch (E:\Fundoo_test\node_modules\@babel\runtime\helpers\regeneratorRuntime.js:86:17)
    at Generator._invoke (E:\Fundoo_test\node_modules\@babel\runtime\helpers\regeneratorRuntime.js:66:24)
    at Generator.next (E:\Fundoo_test\node_modules\@babel\runtime\helpers\regeneratorRuntime.js:117:21)
    at asyncGeneratorStep (E:\Fundoo_test\node_modules\@babel\runtime\helpers\asyncToGenerator.js:3:24)
    at _next (E:\Fundoo_test\node_modules\@babel\runtime\helpers\asyncToGenerator.js:25:9)
    at processTicksAndRejections (node:internal/process/task_queues:96:5) 
    url - /api/v1/note/isarchive/632c85352238172790e2fef9 
    method - PUT 
    IP - ::1
   {"timestamp":"2022-09-22T16:38:58.504Z"}
info: Server started at http://localhost:3000/api/v1/ {"timestamp":"2022-09-22T16:41:32.138Z"}
info: Connected to the database. {"timestamp":"2022-09-22T16:41:32.205Z"}
error: 
    status - 500 
    message - MongooseError: Callback must be a function, got [object Object]
    at Function.Model.$handleCallbackError (E:\Fundoo_test\node_modules\mongoose\lib\model.js:5067:11)
    at Function.findByIdAndUpdate (E:\Fundoo_test\node_modules\mongoose\lib\model.js:2694:19)
    at _callee6$ (E:\Fundoo_test\src\services\/note.service.js:38:27)
    at tryCatch (E:\Fundoo_test\node_modules\@babel\runtime\helpers\regeneratorRuntime.js:86:17)
    at Generator._invoke (E:\Fundoo_test\node_modules\@babel\runtime\helpers\regeneratorRuntime.js:66:24)
    at Generator.next (E:\Fundoo_test\node_modules\@babel\runtime\helpers\regeneratorRuntime.js:117:21)
    at asyncGeneratorStep (E:\Fundoo_test\node_modules\@babel\runtime\helpers\asyncToGenerator.js:3:24)
    at _next (E:\Fundoo_test\node_modules\@babel\runtime\helpers\asyncToGenerator.js:25:9)
    at E:\Fundoo_test\node_modules\@babel\runtime\helpers\asyncToGenerator.js:32:7
    at new Promise (<anonymous>)
    at Object.<anonymous> (E:\Fundoo_test\node_modules\@babel\runtime\helpers\asyncToGenerator.js:21:12)
    at Object.archiveNote (E:\Fundoo_test\src\services\/note.service.js:36:25)
    at _callee6$ (E:\Fundoo_test\src\controllers\/note.controller.js:70:36)
    at tryCatch (E:\Fundoo_test\node_modules\@babel\runtime\helpers\regeneratorRuntime.js:86:17)
    at Generator._invoke (E:\Fundoo_test\node_modules\@babel\runtime\helpers\regeneratorRuntime.js:66:24)
    at Generator.next (E:\Fundoo_test\node_modules\@babel\runtime\helpers\regeneratorRuntime.js:117:21)
    at asyncGeneratorStep (E:\Fundoo_test\node_modules\@babel\runtime\helpers\asyncToGenerator.js:3:24)
    at _next (E:\Fundoo_test\node_modules\@babel\runtime\helpers\asyncToGenerator.js:25:9)
    at E:\Fundoo_test\node_modules\@babel\runtime\helpers\asyncToGenerator.js:32:7
    at new Promise (<anonymous>)
    at E:\Fundoo_test\node_modules\@babel\runtime\helpers\asyncToGenerator.js:21:12
    at archiveNote (E:\Fundoo_test\src\controllers\/note.controller.js:68:25)
    at Layer.handle [as handle_request] (E:\Fundoo_test\node_modules\express\lib\router\layer.js:95:5)
    at next (E:\Fundoo_test\node_modules\express\lib\router\route.js:144:13)
    at _callee$ (E:\Fundoo_test\src\middlewares\/auth.middleware.js:23:5)
    at tryCatch (E:\Fundoo_test\node_modules\@babel\runtime\helpers\regeneratorRuntime.js:86:17)
    at Generator._invoke (E:\Fundoo_test\node_modules\@babel\runtime\helpers\regeneratorRuntime.js:66:24)
    at Generator.next (E:\Fundoo_test\node_modules\@babel\runtime\helpers\regeneratorRuntime.js:117:21)
    at asyncGeneratorStep (E:\Fundoo_test\node_modules\@babel\runtime\helpers\asyncToGenerator.js:3:24)
    at _next (E:\Fundoo_test\node_modules\@babel\runtime\helpers\asyncToGenerator.js:25:9)
    at processTicksAndRejections (node:internal/process/task_queues:96:5) 
    url - /api/v1/note/isarchive/632c85352238172790e2fef9 
    method - PUT 
    IP - ::1
   {"timestamp":"2022-09-22T16:41:32.311Z"}
info: Server started at http://localhost:3000/api/v1/ {"timestamp":"2022-09-22T16:44:29.082Z"}
info: Connected to the database. {"timestamp":"2022-09-22T16:44:29.143Z"}
info: Server started at http://localhost:3000/api/v1/ {"timestamp":"2022-09-22T16:44:48.230Z"}
info: Connected to the database. {"timestamp":"2022-09-22T16:44:48.308Z"}
error: 
    status - 500 
    message - MongooseError: Callback must be a function, got [object Object]
    at Function.Model.$handleCallbackError (E:\Fundoo_test\node_modules\mongoose\lib\model.js:5067:11)
    at Function.findByIdAndUpdate (E:\Fundoo_test\node_modules\mongoose\lib\model.js:2694:19)
    at _callee6$ (E:\Fundoo_test\src\services\/note.service.js:38:27)
    at tryCatch (E:\Fundoo_test\node_modules\@babel\runtime\helpers\regeneratorRuntime.js:86:17)
    at Generator._invoke (E:\Fundoo_test\node_modules\@babel\runtime\helpers\regeneratorRuntime.js:66:24)
    at Generator.next (E:\Fundoo_test\node_modules\@babel\runtime\helpers\regeneratorRuntime.js:117:21)
    at asyncGeneratorStep (E:\Fundoo_test\node_modules\@babel\runtime\helpers\asyncToGenerator.js:3:24)
    at _next (E:\Fundoo_test\node_modules\@babel\runtime\helpers\asyncToGenerator.js:25:9)
    at E:\Fundoo_test\node_modules\@babel\runtime\helpers\asyncToGenerator.js:32:7
    at new Promise (<anonymous>)
    at Object.<anonymous> (E:\Fundoo_test\node_modules\@babel\runtime\helpers\asyncToGenerator.js:21:12)
    at Object.archiveNote (E:\Fundoo_test\src\services\/note.service.js:36:25)
    at _callee6$ (E:\Fundoo_test\src\controllers\/note.controller.js:70:36)
    at tryCatch (E:\Fundoo_test\node_modules\@babel\runtime\helpers\regeneratorRuntime.js:86:17)
    at Generator._invoke (E:\Fundoo_test\node_modules\@babel\runtime\helpers\regeneratorRuntime.js:66:24)
    at Generator.next (E:\Fundoo_test\node_modules\@babel\runtime\helpers\regeneratorRuntime.js:117:21)
    at asyncGeneratorStep (E:\Fundoo_test\node_modules\@babel\runtime\helpers\asyncToGenerator.js:3:24)
    at _next (E:\Fundoo_test\node_modules\@babel\runtime\helpers\asyncToGenerator.js:25:9)
    at E:\Fundoo_test\node_modules\@babel\runtime\helpers\asyncToGenerator.js:32:7
    at new Promise (<anonymous>)
    at E:\Fundoo_test\node_modules\@babel\runtime\helpers\asyncToGenerator.js:21:12
    at archiveNote (E:\Fundoo_test\src\controllers\/note.controller.js:68:25)
    at Layer.handle [as handle_request] (E:\Fundoo_test\node_modules\express\lib\router\layer.js:95:5)
    at next (E:\Fundoo_test\node_modules\express\lib\router\route.js:144:13)
    at _callee$ (E:\Fundoo_test\src\middlewares\/auth.middleware.js:23:5)
    at tryCatch (E:\Fundoo_test\node_modules\@babel\runtime\helpers\regeneratorRuntime.js:86:17)
    at Generator._invoke (E:\Fundoo_test\node_modules\@babel\runtime\helpers\regeneratorRuntime.js:66:24)
    at Generator.next (E:\Fundoo_test\node_modules\@babel\runtime\helpers\regeneratorRuntime.js:117:21)
    at asyncGeneratorStep (E:\Fundoo_test\node_modules\@babel\runtime\helpers\asyncToGenerator.js:3:24)
    at _next (E:\Fundoo_test\node_modules\@babel\runtime\helpers\asyncToGenerator.js:25:9)
    at processTicksAndRejections (node:internal/process/task_queues:96:5) 
    url - /api/v1/note/isarchive/632c85352238172790e2fef9 
    method - PUT 
    IP - ::1
   {"timestamp":"2022-09-22T16:47:00.259Z"}
info: Server started at http://localhost:3000/api/v1/ {"timestamp":"2022-09-22T16:52:03.959Z"}
info: Connected to the database. {"timestamp":"2022-09-22T16:52:03.998Z"}
info: Server started at http://localhost:3000/api/v1/ {"timestamp":"2022-09-22T16:53:42.604Z"}
info: Connected to the database. {"timestamp":"2022-09-22T16:53:42.655Z"}
info: Server started at http://localhost:3000/api/v1/ {"timestamp":"2022-09-22T16:53:48.780Z"}
info: Connected to the database. {"timestamp":"2022-09-22T16:53:48.811Z"}
info: Server started at http://localhost:3000/api/v1/ {"timestamp":"2022-09-22T16:54:18.083Z"}
info: Connected to the database. {"timestamp":"2022-09-22T16:54:18.164Z"}
info: Server started at http://localhost:3000/api/v1/ {"timestamp":"2022-09-22T16:54:32.688Z"}
info: Connected to the database. {"timestamp":"2022-09-22T16:54:32.744Z"}
error: 
    status - 500 
    message - MongooseError: Callback must be a function, got [object Object]
    at Function.Model.$handleCallbackError (E:\Fundoo_test\node_modules\mongoose\lib\model.js:5067:11)
    at Function.findByIdAndUpdate (E:\Fundoo_test\node_modules\mongoose\lib\model.js:2694:19)
    at _callee6$ (E:\Fundoo_test\src\services\/note.service.js:38:27)
    at tryCatch (E:\Fundoo_test\node_modules\@babel\runtime\helpers\regeneratorRuntime.js:86:17)
    at Generator._invoke (E:\Fundoo_test\node_modules\@babel\runtime\helpers\regeneratorRuntime.js:66:24)
    at Generator.next (E:\Fundoo_test\node_modules\@babel\runtime\helpers\regeneratorRuntime.js:117:21)
    at asyncGeneratorStep (E:\Fundoo_test\node_modules\@babel\runtime\helpers\asyncToGenerator.js:3:24)
    at _next (E:\Fundoo_test\node_modules\@babel\runtime\helpers\asyncToGenerator.js:25:9)
    at E:\Fundoo_test\node_modules\@babel\runtime\helpers\asyncToGenerator.js:32:7
    at new Promise (<anonymous>)
    at Object.<anonymous> (E:\Fundoo_test\node_modules\@babel\runtime\helpers\asyncToGenerator.js:21:12)
    at Object.archiveNote (E:\Fundoo_test\src\services\/note.service.js:36:25)
    at _callee6$ (E:\Fundoo_test\src\controllers\/note.controller.js:70:36)
    at tryCatch (E:\Fundoo_test\node_modules\@babel\runtime\helpers\regeneratorRuntime.js:86:17)
    at Generator._invoke (E:\Fundoo_test\node_modules\@babel\runtime\helpers\regeneratorRuntime.js:66:24)
    at Generator.next (E:\Fundoo_test\node_modules\@babel\runtime\helpers\regeneratorRuntime.js:117:21)
    at asyncGeneratorStep (E:\Fundoo_test\node_modules\@babel\runtime\helpers\asyncToGenerator.js:3:24)
    at _next (E:\Fundoo_test\node_modules\@babel\runtime\helpers\asyncToGenerator.js:25:9)
    at E:\Fundoo_test\node_modules\@babel\runtime\helpers\asyncToGenerator.js:32:7
    at new Promise (<anonymous>)
    at E:\Fundoo_test\node_modules\@babel\runtime\helpers\asyncToGenerator.js:21:12
    at archiveNote (E:\Fundoo_test\src\controllers\/note.controller.js:68:25)
    at Layer.handle [as handle_request] (E:\Fundoo_test\node_modules\express\lib\router\layer.js:95:5)
    at next (E:\Fundoo_test\node_modules\express\lib\router\route.js:144:13)
    at _callee$ (E:\Fundoo_test\src\middlewares\/auth.middleware.js:23:5)
    at tryCatch (E:\Fundoo_test\node_modules\@babel\runtime\helpers\regeneratorRuntime.js:86:17)
    at Generator._invoke (E:\Fundoo_test\node_modules\@babel\runtime\helpers\regeneratorRuntime.js:66:24)
    at Generator.next (E:\Fundoo_test\node_modules\@babel\runtime\helpers\regeneratorRuntime.js:117:21)
    at asyncGeneratorStep (E:\Fundoo_test\node_modules\@babel\runtime\helpers\asyncToGenerator.js:3:24)
    at _next (E:\Fundoo_test\node_modules\@babel\runtime\helpers\asyncToGenerator.js:25:9)
    at processTicksAndRejections (node:internal/process/task_queues:96:5) 
    url - /api/v1/note/isarchive/632c85352238172790e2fef9 
    method - PUT 
    IP - ::1
   {"timestamp":"2022-09-22T16:54:39.871Z"}
info: Server started at http://localhost:3000/api/v1/ {"timestamp":"2022-09-22T16:55:08.546Z"}
info: Connected to the database. {"timestamp":"2022-09-22T16:55:08.691Z"}
error: 
    status - 500 
    message - CastError: Cast to ObjectId failed for value "{ _id: undefined }" (type Object) at path "_id" for model "Note"
    at model.Query.exec (E:\Fundoo_test\node_modules\mongoose\lib\query.js:4498:21)
    at model.Query.Query.then (E:\Fundoo_test\node_modules\mongoose\lib\query.js:4592:15)
    at processTicksAndRejections (node:internal/process/task_queues:96:5) 
    url - /api/v1/note/632c85352238172790e2fef9 
    method - PUT 
    IP - ::1
   {"timestamp":"2022-09-22T16:57:45.908Z"}
info: Server started at http://localhost:3000/api/v1/ {"timestamp":"2022-09-22T17:03:18.719Z"}
info: Connected to the database. {"timestamp":"2022-09-22T17:03:18.778Z"}
error: 
    status - 500 
    message - CastError: Cast to ObjectId failed for value "{ _id: undefined }" (type Object) at path "_id" for model "Note"
    at model.Query.exec (E:\Fundoo_test\node_modules\mongoose\lib\query.js:4498:21)
    at model.Query.Query.then (E:\Fundoo_test\node_modules\mongoose\lib\query.js:4592:15)
    at processTicksAndRejections (node:internal/process/task_queues:96:5) 
    url - /api/v1/note/632c85352238172790e2fef9 
    method - PUT 
    IP - ::1
   {"timestamp":"2022-09-22T17:03:19.351Z"}
error: 
    status - 500 
    message - CastError: Cast to ObjectId failed for value "{ _id: undefined }" (type Object) at path "_id" for model "Note"
    at model.Query.exec (E:\Fundoo_test\node_modules\mongoose\lib\query.js:4498:21)
    at model.Query.Query.then (E:\Fundoo_test\node_modules\mongoose\lib\query.js:4592:15)
    at processTicksAndRejections (node:internal/process/task_queues:96:5) 
    url - /api/v1/note/632c85352238172790e2fef9 
    method - PUT 
    IP - ::1
   {"timestamp":"2022-09-22T17:03:22.323Z"}
info: Server started at http://localhost:3000/api/v1/ {"timestamp":"2022-09-22T17:03:59.026Z"}
info: Connected to the database. {"timestamp":"2022-09-22T17:03:59.084Z"}
info: Server started at http://localhost:3000/api/v1/ {"timestamp":"2022-09-22T17:04:34.988Z"}
info: Connected to the database. {"timestamp":"2022-09-22T17:04:35.091Z"}
info: Server started at http://localhost:3000/api/v1/ {"timestamp":"2022-09-22T17:04:47.969Z"}
info: Connected to the database. {"timestamp":"2022-09-22T17:04:48.004Z"}
error: 
    status - 500 
    message - CastError: Cast to ObjectId failed for value "{ _id: undefined }" (type Object) at path "_id" for model "Note"
    at model.Query.exec (E:\Fundoo_test\node_modules\mongoose\lib\query.js:4498:21)
    at model.Query.Query.then (E:\Fundoo_test\node_modules\mongoose\lib\query.js:4592:15)
    at processTicksAndRejections (node:internal/process/task_queues:96:5) 
    url - /api/v1/note/632c85352238172790e2fef9 
    method - PUT 
    IP - ::1
   {"timestamp":"2022-09-22T17:04:58.758Z"}
error: 
    status - 500 
    message - MongooseError: Callback must be a function, got [object Object]
    at Function.Model.$handleCallbackError (E:\Fundoo_test\node_modules\mongoose\lib\model.js:5067:11)
    at Function.findByIdAndUpdate (E:\Fundoo_test\node_modules\mongoose\lib\model.js:2694:19)
    at _callee6$ (E:\Fundoo_test\src\services\/note.service.js:38:27)
    at tryCatch (E:\Fundoo_test\node_modules\@babel\runtime\helpers\regeneratorRuntime.js:86:17)
    at Generator._invoke (E:\Fundoo_test\node_modules\@babel\runtime\helpers\regeneratorRuntime.js:66:24)
    at Generator.next (E:\Fundoo_test\node_modules\@babel\runtime\helpers\regeneratorRuntime.js:117:21)
    at asyncGeneratorStep (E:\Fundoo_test\node_modules\@babel\runtime\helpers\asyncToGenerator.js:3:24)
    at _next (E:\Fundoo_test\node_modules\@babel\runtime\helpers\asyncToGenerator.js:25:9)
    at E:\Fundoo_test\node_modules\@babel\runtime\helpers\asyncToGenerator.js:32:7
    at new Promise (<anonymous>)
    at Object.<anonymous> (E:\Fundoo_test\node_modules\@babel\runtime\helpers\asyncToGenerator.js:21:12)
    at Object.archiveNote (E:\Fundoo_test\src\services\/note.service.js:36:25)
    at _callee6$ (E:\Fundoo_test\src\controllers\/note.controller.js:70:36)
    at tryCatch (E:\Fundoo_test\node_modules\@babel\runtime\helpers\regeneratorRuntime.js:86:17)
    at Generator._invoke (E:\Fundoo_test\node_modules\@babel\runtime\helpers\regeneratorRuntime.js:66:24)
    at Generator.next (E:\Fundoo_test\node_modules\@babel\runtime\helpers\regeneratorRuntime.js:117:21)
    at asyncGeneratorStep (E:\Fundoo_test\node_modules\@babel\runtime\helpers\asyncToGenerator.js:3:24)
    at _next (E:\Fundoo_test\node_modules\@babel\runtime\helpers\asyncToGenerator.js:25:9)
    at E:\Fundoo_test\node_modules\@babel\runtime\helpers\asyncToGenerator.js:32:7
    at new Promise (<anonymous>)
    at E:\Fundoo_test\node_modules\@babel\runtime\helpers\asyncToGenerator.js:21:12
    at archiveNote (E:\Fundoo_test\src\controllers\/note.controller.js:68:25)
    at Layer.handle [as handle_request] (E:\Fundoo_test\node_modules\express\lib\router\layer.js:95:5)
    at next (E:\Fundoo_test\node_modules\express\lib\router\route.js:144:13)
    at _callee$ (E:\Fundoo_test\src\middlewares\/auth.middleware.js:23:5)
    at tryCatch (E:\Fundoo_test\node_modules\@babel\runtime\helpers\regeneratorRuntime.js:86:17)
    at Generator._invoke (E:\Fundoo_test\node_modules\@babel\runtime\helpers\regeneratorRuntime.js:66:24)
    at Generator.next (E:\Fundoo_test\node_modules\@babel\runtime\helpers\regeneratorRuntime.js:117:21)
    at asyncGeneratorStep (E:\Fundoo_test\node_modules\@babel\runtime\helpers\asyncToGenerator.js:3:24)
    at _next (E:\Fundoo_test\node_modules\@babel\runtime\helpers\asyncToGenerator.js:25:9)
    at processTicksAndRejections (node:internal/process/task_queues:96:5) 
    url - /api/v1/note/isarchive/632c7e8507977f23ac7ee7cc 
    method - PUT 
    IP - ::1
   {"timestamp":"2022-09-22T17:06:37.821Z"}
error: 
    status - 500 
    message - MongooseError: Callback must be a function, got [object Object]
    at Function.Model.$handleCallbackError (E:\Fundoo_test\node_modules\mongoose\lib\model.js:5067:11)
    at Function.findByIdAndUpdate (E:\Fundoo_test\node_modules\mongoose\lib\model.js:2694:19)
    at _callee6$ (E:\Fundoo_test\src\services\/note.service.js:38:27)
    at tryCatch (E:\Fundoo_test\node_modules\@babel\runtime\helpers\regeneratorRuntime.js:86:17)
    at Generator._invoke (E:\Fundoo_test\node_modules\@babel\runtime\helpers\regeneratorRuntime.js:66:24)
    at Generator.next (E:\Fundoo_test\node_modules\@babel\runtime\helpers\regeneratorRuntime.js:117:21)
    at asyncGeneratorStep (E:\Fundoo_test\node_modules\@babel\runtime\helpers\asyncToGenerator.js:3:24)
    at _next (E:\Fundoo_test\node_modules\@babel\runtime\helpers\asyncToGenerator.js:25:9)
    at E:\Fundoo_test\node_modules\@babel\runtime\helpers\asyncToGenerator.js:32:7
    at new Promise (<anonymous>)
    at Object.<anonymous> (E:\Fundoo_test\node_modules\@babel\runtime\helpers\asyncToGenerator.js:21:12)
    at Object.archiveNote (E:\Fundoo_test\src\services\/note.service.js:36:25)
    at _callee6$ (E:\Fundoo_test\src\controllers\/note.controller.js:70:36)
    at tryCatch (E:\Fundoo_test\node_modules\@babel\runtime\helpers\regeneratorRuntime.js:86:17)
    at Generator._invoke (E:\Fundoo_test\node_modules\@babel\runtime\helpers\regeneratorRuntime.js:66:24)
    at Generator.next (E:\Fundoo_test\node_modules\@babel\runtime\helpers\regeneratorRuntime.js:117:21)
    at asyncGeneratorStep (E:\Fundoo_test\node_modules\@babel\runtime\helpers\asyncToGenerator.js:3:24)
    at _next (E:\Fundoo_test\node_modules\@babel\runtime\helpers\asyncToGenerator.js:25:9)
    at E:\Fundoo_test\node_modules\@babel\runtime\helpers\asyncToGenerator.js:32:7
    at new Promise (<anonymous>)
    at E:\Fundoo_test\node_modules\@babel\runtime\helpers\asyncToGenerator.js:21:12
    at archiveNote (E:\Fundoo_test\src\controllers\/note.controller.js:68:25)
    at Layer.handle [as handle_request] (E:\Fundoo_test\node_modules\express\lib\router\layer.js:95:5)
    at next (E:\Fundoo_test\node_modules\express\lib\router\route.js:144:13)
    at _callee$ (E:\Fundoo_test\src\middlewares\/auth.middleware.js:23:5)
    at tryCatch (E:\Fundoo_test\node_modules\@babel\runtime\helpers\regeneratorRuntime.js:86:17)
    at Generator._invoke (E:\Fundoo_test\node_modules\@babel\runtime\helpers\regeneratorRuntime.js:66:24)
    at Generator.next (E:\Fundoo_test\node_modules\@babel\runtime\helpers\regeneratorRuntime.js:117:21)
    at asyncGeneratorStep (E:\Fundoo_test\node_modules\@babel\runtime\helpers\asyncToGenerator.js:3:24)
    at _next (E:\Fundoo_test\node_modules\@babel\runtime\helpers\asyncToGenerator.js:25:9)
    at processTicksAndRejections (node:internal/process/task_queues:96:5) 
    url - /api/v1/note/isarchive/632c7e8507977f23ac7ee7cc 
    method - PUT 
    IP - ::1
   {"timestamp":"2022-09-22T17:09:04.114Z"}
info: Server started at http://localhost:3000/api/v1/ {"timestamp":"2022-09-22T17:11:35.921Z"}
info: Connected to the database. {"timestamp":"2022-09-22T17:11:35.947Z"}
error: 
    status - 500 
    message - CastError: Cast to ObjectId failed for value "{ _id: undefined }" (type Object) at path "_id" for model "Note"
    at model.Query.exec (E:\Fundoo_test\node_modules\mongoose\lib\query.js:4498:21)
    at model.Query.Query.then (E:\Fundoo_test\node_modules\mongoose\lib\query.js:4592:15)
    at processTicksAndRejections (node:internal/process/task_queues:96:5) 
    url - /api/v1/note/632c85352238172790e2fef9 
    method - PUT 
    IP - ::1
   {"timestamp":"2022-09-22T17:12:04.484Z"}
info: Server started at http://localhost:3000/api/v1/ {"timestamp":"2022-09-22T17:12:38.099Z"}
info: Connected to the database. {"timestamp":"2022-09-22T17:12:38.246Z"}
error: 
    status - 500 
    message - CastError: Cast to ObjectId failed for value "{ _id: undefined }" (type Object) at path "_id" for model "Note"
    at model.Query.exec (E:\Fundoo_test\node_modules\mongoose\lib\query.js:4498:21)
    at model.Query.Query.then (E:\Fundoo_test\node_modules\mongoose\lib\query.js:4592:15)
    at processTicksAndRejections (node:internal/process/task_queues:96:5) 
    url - /api/v1/note/632c85352238172790e2fef9 
    method - PUT 
    IP - ::1
   {"timestamp":"2022-09-22T17:12:38.573Z"}
info: Server started at http://localhost:3000/api/v1/ {"timestamp":"2022-09-22T17:17:41.582Z"}
info: Connected to the database. {"timestamp":"2022-09-22T17:17:41.661Z"}
error: 
    status - 500 
    message - CastError: Cast to ObjectId failed for value "{ _id: undefined }" (type Object) at path "_id" for model "Note"
    at model.Query.exec (E:\Fundoo_test\node_modules\mongoose\lib\query.js:4498:21)
    at model.Query.Query.then (E:\Fundoo_test\node_modules\mongoose\lib\query.js:4592:15)
    at processTicksAndRejections (node:internal/process/task_queues:96:5) 
    url - /api/v1/note/632c85352238172790e2fef9 
    method - PUT 
    IP - ::1
   {"timestamp":"2022-09-22T17:17:51.602Z"}
info: Server started at http://localhost:3000/api/v1/ {"timestamp":"2022-09-22T17:24:38.369Z"}
info: Connected to the database. {"timestamp":"2022-09-22T17:24:38.461Z"}
error: 
    status - 500 
    message - CastError: Cast to ObjectId failed for value "{ _id: undefined }" (type Object) at path "_id" for model "Note"
    at model.Query.exec (E:\Fundoo_test\node_modules\mongoose\lib\query.js:4498:21)
    at model.Query.Query.then (E:\Fundoo_test\node_modules\mongoose\lib\query.js:4592:15)
    at processTicksAndRejections (node:internal/process/task_queues:96:5) 
    url - /api/v1/note/632c85352238172790e2fef9 
    method - PUT 
    IP - ::1
   {"timestamp":"2022-09-22T17:25:03.172Z"}
error: 
    status - 500 
    message - CastError: Cast to ObjectId failed for value "{ _id: undefined }" (type Object) at path "_id" for model "Note"
    at model.Query.exec (E:\Fundoo_test\node_modules\mongoose\lib\query.js:4498:21)
    at model.Query.Query.then (E:\Fundoo_test\node_modules\mongoose\lib\query.js:4592:15)
    at processTicksAndRejections (node:internal/process/task_queues:96:5) 
    url - /api/v1/note/632c85352238172790e2fef9 
    method - PUT 
    IP - ::1
   {"timestamp":"2022-09-22T17:25:23.442Z"}
info: Server started at http://localhost:3000/api/v1/ {"timestamp":"2022-09-22T17:25:50.676Z"}
info: Connected to the database. {"timestamp":"2022-09-22T17:25:50.713Z"}
error: 
    status - 500 
    message - CastError: Cast to ObjectId failed for value "{ _id: undefined }" (type Object) at path "_id" for model "Note"
    at model.Query.exec (E:\Fundoo_test\node_modules\mongoose\lib\query.js:4498:21)
    at model.Query.Query.then (E:\Fundoo_test\node_modules\mongoose\lib\query.js:4592:15)
    at processTicksAndRejections (node:internal/process/task_queues:96:5) 
    url - /api/v1/note/632c85352238172790e2fef9 
    method - PUT 
    IP - ::1
   {"timestamp":"2022-09-22T17:27:46.599Z"}
info: Server started at http://localhost:3000/api/v1/ {"timestamp":"2022-09-22T17:32:48.988Z"}
info: Connected to the database. {"timestamp":"2022-09-22T17:32:49.106Z"}
error: 
    status - 500 
    message - CastError: Cast to ObjectId failed for value "{ _id: undefined }" (type Object) at path "_id" for model "Note"
    at model.Query.exec (E:\Fundoo_test\node_modules\mongoose\lib\query.js:4498:21)
    at model.Query.Query.then (E:\Fundoo_test\node_modules\mongoose\lib\query.js:4592:15)
    at processTicksAndRejections (node:internal/process/task_queues:96:5) 
    url - /api/v1/note/632c85352238172790e2fef9 
    method - PUT 
    IP - ::1
   {"timestamp":"2022-09-22T17:32:50.656Z"}
info: Server started at http://localhost:3000/api/v1/ {"timestamp":"2022-09-22T17:33:13.171Z"}
info: Connected to the database. {"timestamp":"2022-09-22T17:33:13.212Z"}
error: 
    status - 500 
    message - CastError: Cast to ObjectId failed for value "{ _id: undefined }" (type Object) at path "_id" for model "Note"
    at model.Query.exec (E:\Fundoo_test\node_modules\mongoose\lib\query.js:4498:21)
    at model.Query.Query.then (E:\Fundoo_test\node_modules\mongoose\lib\query.js:4592:15)
    at processTicksAndRejections (node:internal/process/task_queues:96:5) 
    url - /api/v1/note/632c85352238172790e2fef9 
    method - PUT 
    IP - ::1
   {"timestamp":"2022-09-22T17:51:09.215Z"}
info: Server started at http://localhost:3000/api/v1/ {"timestamp":"2022-09-22T17:54:49.213Z"}
info: Connected to the database. {"timestamp":"2022-09-22T17:54:49.249Z"}
info: Server started at http://localhost:3000/api/v1/ {"timestamp":"2022-09-22T17:54:58.108Z"}
info: Connected to the database. {"timestamp":"2022-09-22T17:54:58.142Z"}
error: 
    status - 500 
    message - CastError: Cast to ObjectId failed for value "{ _id: undefined }" (type Object) at path "_id" for model "Note"
    at model.Query.exec (E:\Fundoo_test\node_modules\mongoose\lib\query.js:4498:21)
    at model.Query.Query.then (E:\Fundoo_test\node_modules\mongoose\lib\query.js:4592:15)
    at processTicksAndRejections (node:internal/process/task_queues:96:5) 
    url - /api/v1/note/632c85352238172790e2fef9 
    method - PUT 
    IP - ::1
   {"timestamp":"2022-09-22T17:55:19.857Z"}
error: 
    status - 500 
    message - CastError: Cast to ObjectId failed for value "{ _id: undefined }" (type Object) at path "_id" for model "Note"
    at model.Query.exec (E:\Fundoo_test\node_modules\mongoose\lib\query.js:4498:21)
    at model.Query.Query.then (E:\Fundoo_test\node_modules\mongoose\lib\query.js:4592:15)
    at processTicksAndRejections (node:internal/process/task_queues:96:5) 
    url - /api/v1/note/632c85352238172790e2fef9 
    method - PUT 
    IP - ::1
   {"timestamp":"2022-09-22T17:55:21.303Z"}
info: Server started at http://localhost:3000/api/v1/ {"timestamp":"2022-09-22T17:56:13.364Z"}
info: Connected to the database. {"timestamp":"2022-09-22T17:56:13.413Z"}
error: 
    status - 500 
    message - CastError: Cast to ObjectId failed for value "{ _id: undefined }" (type Object) at path "_id" for model "Note"
    at model.Query.exec (E:\Fundoo_test\node_modules\mongoose\lib\query.js:4498:21)
    at model.Query.Query.then (E:\Fundoo_test\node_modules\mongoose\lib\query.js:4592:15)
    at processTicksAndRejections (node:internal/process/task_queues:96:5) 
    url - /api/v1/note/632c85352238172790e2fef9 
    method - PUT 
    IP - ::1
   {"timestamp":"2022-09-22T17:58:49.887Z"}
info: Server started at http://localhost:3000/api/v1/ {"timestamp":"2022-09-22T18:23:33.239Z"}
info: Connected to the database. {"timestamp":"2022-09-22T18:23:33.266Z"}
info: Server started at http://localhost:3000/api/v1/ {"timestamp":"2022-09-22T18:25:13.122Z"}
info: Connected to the database. {"timestamp":"2022-09-22T18:25:13.166Z"}
error: 
    status - 500 
    message - ReferenceError: id is not defined
    at _callee4$ (E:\Fundoo_test\src\services\/note.service.js:25:7)
    at tryCatch (E:\Fundoo_test\node_modules\@babel\runtime\helpers\regeneratorRuntime.js:86:17)
    at Generator._invoke (E:\Fundoo_test\node_modules\@babel\runtime\helpers\regeneratorRuntime.js:66:24)
    at Generator.next (E:\Fundoo_test\node_modules\@babel\runtime\helpers\regeneratorRuntime.js:117:21)
    at asyncGeneratorStep (E:\Fundoo_test\node_modules\@babel\runtime\helpers\asyncToGenerator.js:3:24)
    at _next (E:\Fundoo_test\node_modules\@babel\runtime\helpers\asyncToGenerator.js:25:9)
    at E:\Fundoo_test\node_modules\@babel\runtime\helpers\asyncToGenerator.js:32:7
    at new Promise (<anonymous>)
    at Object.<anonymous> (E:\Fundoo_test\node_modules\@babel\runtime\helpers\asyncToGenerator.js:21:12)
    at Object.updateNote (E:\Fundoo_test\src\services\/note.service.js:21:24)
    at _callee4$ (E:\Fundoo_test\src\controllers\/note.controller.js:45:36)
    at tryCatch (E:\Fundoo_test\node_modules\@babel\runtime\helpers\regeneratorRuntime.js:86:17)
    at Generator._invoke (E:\Fundoo_test\node_modules\@babel\runtime\helpers\regeneratorRuntime.js:66:24)
    at Generator.next (E:\Fundoo_test\node_modules\@babel\runtime\helpers\regeneratorRuntime.js:117:21)
    at asyncGeneratorStep (E:\Fundoo_test\node_modules\@babel\runtime\helpers\asyncToGenerator.js:3:24)
    at _next (E:\Fundoo_test\node_modules\@babel\runtime\helpers\asyncToGenerator.js:25:9)
    at E:\Fundoo_test\node_modules\@babel\runtime\helpers\asyncToGenerator.js:32:7
    at new Promise (<anonymous>)
    at E:\Fundoo_test\node_modules\@babel\runtime\helpers\asyncToGenerator.js:21:12
    at updateNote (E:\Fundoo_test\src\controllers\/note.controller.js:43:24)
    at Layer.handle [as handle_request] (E:\Fundoo_test\node_modules\express\lib\router\layer.js:95:5)
    at next (E:\Fundoo_test\node_modules\express\lib\router\route.js:144:13)
    at _callee$ (E:\Fundoo_test\src\middlewares\/auth.middleware.js:23:5)
    at tryCatch (E:\Fundoo_test\node_modules\@babel\runtime\helpers\regeneratorRuntime.js:86:17)
    at Generator._invoke (E:\Fundoo_test\node_modules\@babel\runtime\helpers\regeneratorRuntime.js:66:24)
    at Generator.next (E:\Fundoo_test\node_modules\@babel\runtime\helpers\regeneratorRuntime.js:117:21)
    at asyncGeneratorStep (E:\Fundoo_test\node_modules\@babel\runtime\helpers\asyncToGenerator.js:3:24)
    at _next (E:\Fundoo_test\node_modules\@babel\runtime\helpers\asyncToGenerator.js:25:9)
    at processTicksAndRejections (node:internal/process/task_queues:96:5) 
    url - /api/v1/note/632c7e8507977f23ac7ee7cc 
    method - PUT 
    IP - ::1
   {"timestamp":"2022-09-22T18:25:59.348Z"}
error: 
    status - 500 
    message - ReferenceError: id is not defined
    at _callee4$ (E:\Fundoo_test\src\services\/note.service.js:25:7)
    at tryCatch (E:\Fundoo_test\node_modules\@babel\runtime\helpers\regeneratorRuntime.js:86:17)
    at Generator._invoke (E:\Fundoo_test\node_modules\@babel\runtime\helpers\regeneratorRuntime.js:66:24)
    at Generator.next (E:\Fundoo_test\node_modules\@babel\runtime\helpers\regeneratorRuntime.js:117:21)
    at asyncGeneratorStep (E:\Fundoo_test\node_modules\@babel\runtime\helpers\asyncToGenerator.js:3:24)
    at _next (E:\Fundoo_test\node_modules\@babel\runtime\helpers\asyncToGenerator.js:25:9)
    at E:\Fundoo_test\node_modules\@babel\runtime\helpers\asyncToGenerator.js:32:7
    at new Promise (<anonymous>)
    at Object.<anonymous> (E:\Fundoo_test\node_modules\@babel\runtime\helpers\asyncToGenerator.js:21:12)
    at Object.updateNote (E:\Fundoo_test\src\services\/note.service.js:21:24)
    at _callee4$ (E:\Fundoo_test\src\controllers\/note.controller.js:45:36)
    at tryCatch (E:\Fundoo_test\node_modules\@babel\runtime\helpers\regeneratorRuntime.js:86:17)
    at Generator._invoke (E:\Fundoo_test\node_modules\@babel\runtime\helpers\regeneratorRuntime.js:66:24)
    at Generator.next (E:\Fundoo_test\node_modules\@babel\runtime\helpers\regeneratorRuntime.js:117:21)
    at asyncGeneratorStep (E:\Fundoo_test\node_modules\@babel\runtime\helpers\asyncToGenerator.js:3:24)
    at _next (E:\Fundoo_test\node_modules\@babel\runtime\helpers\asyncToGenerator.js:25:9)
    at E:\Fundoo_test\node_modules\@babel\runtime\helpers\asyncToGenerator.js:32:7
    at new Promise (<anonymous>)
    at E:\Fundoo_test\node_modules\@babel\runtime\helpers\asyncToGenerator.js:21:12
    at updateNote (E:\Fundoo_test\src\controllers\/note.controller.js:43:24)
    at Layer.handle [as handle_request] (E:\Fundoo_test\node_modules\express\lib\router\layer.js:95:5)
    at next (E:\Fundoo_test\node_modules\express\lib\router\route.js:144:13)
    at _callee$ (E:\Fundoo_test\src\middlewares\/auth.middleware.js:23:5)
    at tryCatch (E:\Fundoo_test\node_modules\@babel\runtime\helpers\regeneratorRuntime.js:86:17)
    at Generator._invoke (E:\Fundoo_test\node_modules\@babel\runtime\helpers\regeneratorRuntime.js:66:24)
    at Generator.next (E:\Fundoo_test\node_modules\@babel\runtime\helpers\regeneratorRuntime.js:117:21)
    at asyncGeneratorStep (E:\Fundoo_test\node_modules\@babel\runtime\helpers\asyncToGenerator.js:3:24)
    at _next (E:\Fundoo_test\node_modules\@babel\runtime\helpers\asyncToGenerator.js:25:9)
    at processTicksAndRejections (node:internal/process/task_queues:96:5) 
    url - /api/v1/note/632c7e8507977f23ac7ee7cc 
    method - PUT 
    IP - ::1
   {"timestamp":"2022-09-22T18:26:05.361Z"}
error: 
    status - 500 
    message - ReferenceError: id is not defined
    at _callee4$ (E:\Fundoo_test\src\services\/note.service.js:25:7)
    at tryCatch (E:\Fundoo_test\node_modules\@babel\runtime\helpers\regeneratorRuntime.js:86:17)
    at Generator._invoke (E:\Fundoo_test\node_modules\@babel\runtime\helpers\regeneratorRuntime.js:66:24)
    at Generator.next (E:\Fundoo_test\node_modules\@babel\runtime\helpers\regeneratorRuntime.js:117:21)
    at asyncGeneratorStep (E:\Fundoo_test\node_modules\@babel\runtime\helpers\asyncToGenerator.js:3:24)
    at _next (E:\Fundoo_test\node_modules\@babel\runtime\helpers\asyncToGenerator.js:25:9)
    at E:\Fundoo_test\node_modules\@babel\runtime\helpers\asyncToGenerator.js:32:7
    at new Promise (<anonymous>)
    at Object.<anonymous> (E:\Fundoo_test\node_modules\@babel\runtime\helpers\asyncToGenerator.js:21:12)
    at Object.updateNote (E:\Fundoo_test\src\services\/note.service.js:21:24)
    at _callee4$ (E:\Fundoo_test\src\controllers\/note.controller.js:45:36)
    at tryCatch (E:\Fundoo_test\node_modules\@babel\runtime\helpers\regeneratorRuntime.js:86:17)
    at Generator._invoke (E:\Fundoo_test\node_modules\@babel\runtime\helpers\regeneratorRuntime.js:66:24)
    at Generator.next (E:\Fundoo_test\node_modules\@babel\runtime\helpers\regeneratorRuntime.js:117:21)
    at asyncGeneratorStep (E:\Fundoo_test\node_modules\@babel\runtime\helpers\asyncToGenerator.js:3:24)
    at _next (E:\Fundoo_test\node_modules\@babel\runtime\helpers\asyncToGenerator.js:25:9)
    at E:\Fundoo_test\node_modules\@babel\runtime\helpers\asyncToGenerator.js:32:7
    at new Promise (<anonymous>)
    at E:\Fundoo_test\node_modules\@babel\runtime\helpers\asyncToGenerator.js:21:12
    at updateNote (E:\Fundoo_test\src\controllers\/note.controller.js:43:24)
    at Layer.handle [as handle_request] (E:\Fundoo_test\node_modules\express\lib\router\layer.js:95:5)
    at next (E:\Fundoo_test\node_modules\express\lib\router\route.js:144:13)
    at _callee$ (E:\Fundoo_test\src\middlewares\/auth.middleware.js:23:5)
    at tryCatch (E:\Fundoo_test\node_modules\@babel\runtime\helpers\regeneratorRuntime.js:86:17)
    at Generator._invoke (E:\Fundoo_test\node_modules\@babel\runtime\helpers\regeneratorRuntime.js:66:24)
    at Generator.next (E:\Fundoo_test\node_modules\@babel\runtime\helpers\regeneratorRuntime.js:117:21)
    at asyncGeneratorStep (E:\Fundoo_test\node_modules\@babel\runtime\helpers\asyncToGenerator.js:3:24)
    at _next (E:\Fundoo_test\node_modules\@babel\runtime\helpers\asyncToGenerator.js:25:9)
    at processTicksAndRejections (node:internal/process/task_queues:96:5) 
    url - /api/v1/note/632c7e8507977f23ac7ee7cc 
    method - PUT 
    IP - ::1
   {"timestamp":"2022-09-22T18:26:06.768Z"}
error: 
    status - 500 
    message - ReferenceError: id is not defined
    at _callee4$ (E:\Fundoo_test\src\services\/note.service.js:25:7)
    at tryCatch (E:\Fundoo_test\node_modules\@babel\runtime\helpers\regeneratorRuntime.js:86:17)
    at Generator._invoke (E:\Fundoo_test\node_modules\@babel\runtime\helpers\regeneratorRuntime.js:66:24)
    at Generator.next (E:\Fundoo_test\node_modules\@babel\runtime\helpers\regeneratorRuntime.js:117:21)
    at asyncGeneratorStep (E:\Fundoo_test\node_modules\@babel\runtime\helpers\asyncToGenerator.js:3:24)
    at _next (E:\Fundoo_test\node_modules\@babel\runtime\helpers\asyncToGenerator.js:25:9)
    at E:\Fundoo_test\node_modules\@babel\runtime\helpers\asyncToGenerator.js:32:7
    at new Promise (<anonymous>)
    at Object.<anonymous> (E:\Fundoo_test\node_modules\@babel\runtime\helpers\asyncToGenerator.js:21:12)
    at Object.updateNote (E:\Fundoo_test\src\services\/note.service.js:21:24)
    at _callee4$ (E:\Fundoo_test\src\controllers\/note.controller.js:45:36)
    at tryCatch (E:\Fundoo_test\node_modules\@babel\runtime\helpers\regeneratorRuntime.js:86:17)
    at Generator._invoke (E:\Fundoo_test\node_modules\@babel\runtime\helpers\regeneratorRuntime.js:66:24)
    at Generator.next (E:\Fundoo_test\node_modules\@babel\runtime\helpers\regeneratorRuntime.js:117:21)
    at asyncGeneratorStep (E:\Fundoo_test\node_modules\@babel\runtime\helpers\asyncToGenerator.js:3:24)
    at _next (E:\Fundoo_test\node_modules\@babel\runtime\helpers\asyncToGenerator.js:25:9)
    at E:\Fundoo_test\node_modules\@babel\runtime\helpers\asyncToGenerator.js:32:7
    at new Promise (<anonymous>)
    at E:\Fundoo_test\node_modules\@babel\runtime\helpers\asyncToGenerator.js:21:12
    at updateNote (E:\Fundoo_test\src\controllers\/note.controller.js:43:24)
    at Layer.handle [as handle_request] (E:\Fundoo_test\node_modules\express\lib\router\layer.js:95:5)
    at next (E:\Fundoo_test\node_modules\express\lib\router\route.js:144:13)
    at _callee$ (E:\Fundoo_test\src\middlewares\/auth.middleware.js:23:5)
    at tryCatch (E:\Fundoo_test\node_modules\@babel\runtime\helpers\regeneratorRuntime.js:86:17)
    at Generator._invoke (E:\Fundoo_test\node_modules\@babel\runtime\helpers\regeneratorRuntime.js:66:24)
    at Generator.next (E:\Fundoo_test\node_modules\@babel\runtime\helpers\regeneratorRuntime.js:117:21)
    at asyncGeneratorStep (E:\Fundoo_test\node_modules\@babel\runtime\helpers\asyncToGenerator.js:3:24)
    at _next (E:\Fundoo_test\node_modules\@babel\runtime\helpers\asyncToGenerator.js:25:9)
    at processTicksAndRejections (node:internal/process/task_queues:96:5) 
    url - /api/v1/note/632c7e8507977f23ac7ee7cc 
    method - PUT 
    IP - ::1
   {"timestamp":"2022-09-22T18:26:07.974Z"}
info: Server started at http://localhost:3000/api/v1/ {"timestamp":"2022-09-22T18:26:38.202Z"}
info: Connected to the database. {"timestamp":"2022-09-22T18:26:38.425Z"}
error: 
    status - 500 
    message - CastError: Cast to ObjectId failed for value "{ _id: undefined }" (type Object) at path "_id" for model "Note"
    at model.Query.exec (E:\Fundoo_test\node_modules\mongoose\lib\query.js:4498:21)
    at model.Query.Query.then (E:\Fundoo_test\node_modules\mongoose\lib\query.js:4592:15)
    at processTicksAndRejections (node:internal/process/task_queues:96:5) 
    url - /api/v1/note/632c7e8507977f23ac7ee7cc 
    method - PUT 
    IP - ::1
   {"timestamp":"2022-09-22T18:26:38.429Z"}
info: Server started at http://localhost:3000/api/v1/ {"timestamp":"2022-09-22T18:27:39.780Z"}
info: Connected to the database. {"timestamp":"2022-09-22T18:27:39.819Z"}
error: 
    status - 500 
    message - CastError: Cast to ObjectId failed for value "{ _id: undefined }" (type Object) at path "_id" for model "Note"
    at model.Query.exec (E:\Fundoo_test\node_modules\mongoose\lib\query.js:4498:21)
    at model.Query.Query.then (E:\Fundoo_test\node_modules\mongoose\lib\query.js:4592:15)
    at processTicksAndRejections (node:internal/process/task_queues:96:5) 
    url - /api/v1/note/632c7e8507977f23ac7ee7cc 
    method - PUT 
    IP - ::1
   {"timestamp":"2022-09-22T18:27:51.628Z"}
